Workbook

Sheet MASTER
A1: DASHBOARD CONSOLIDADO - GRUPO DELGA 2026
A2: Atualizado: | B2: 13/01/2026 | D2: Semana:
A4: VISÃO GERAL - BIG NUMBERS
A5: META ANUAL | C5: REALIZADO YTD | E5: % ATINGIMENTO | G5: GAP | I5: PROJETOS ATIVOS | K5: KAIZENS
A6: R$ 50,32 Mi | C6: R$ 0 | E6: 0% | G6: R$ 50,32 Mi | I6: 0 | K6: 0
A8: SAVING POR FONTE
A9: FONTE | B9: META | C9: REALIZADO | D9: % ATING. | E9: GAP | F9: STATUS
A10: Diadema | B10: 6947000 | C10: 0 | D10: =IF(B10=0,0,C10/B10) -> 0 | E10: =B10-C10 -> 6947000
A11: Ferraz | B11: 13367000 | C11: 0 | D11: =IF(B11=0,0,C11/B11) -> 0 | E11: =B11-C11 -> 13367000
A12: São Leopoldo | B12: 2100000 | C12: 0 | D12: =IF(B12=0,0,C12/B12) -> 0 | E12: =B12-C12 -> 2100000
A13: Jarinu | B13: 5356000 | C13: 0 | D13: =IF(B13=0,0,C13/B13) -> 0 | E13: =B13-C13 -> 5356000
A14: Anchieta | B14: 3841000 | C14: 0 | D14: =IF(B14=0,0,C14/B14) -> 0 | E14: =B14-C14 -> 3841000
A15: Compras | B15: 7000000 | C15: 0 | D15: =IF(B15=0,0,C15/B15) -> 0 | E15: =B15-C15 -> 7000000
A16: Vendas | B16: 10000000 | C16: 0 | D16: =IF(B16=0,0,C16/B16) -> 0 | E16: =B16-C16 -> 10000000
A17: Corporativo | B17: 1709000
A18: TOTAL | B18: =SUM(B10:B16) -> 48611000 | C18: =SUM(C10:C16) -> 0 | D18: =IF(B18=0,0,C18/B18) -> 0 | E18: =B18-C18 -> 48611000
A20: KPIs OPERACIONAIS - COMPARATIVO UNIDADES
A21: KPI | B21: META | C21: DIADEMA | D21: FERRAZ | E21: SÃO LEOPOLDO | F21: JARINU | G21: ANCHIETA | H21: MÉDIA | I21: STATUS
H22: =AVERAGE(C22:G22) -> #DIV/0!
H23: =AVERAGE(C23:G23) -> #DIV/0!
H24: =AVERAGE(C24:G24) -> #DIV/0!
H25: =AVERAGE(C25:G25) -> #DIV/0!
H26: =AVERAGE(C26:G26) -> #DIV/0!
H27: =AVERAGE(C27:G27) -> #DIV/0!
H28: =AVERAGE(C28:G28) -> #DIV/0!
H29: =AVERAGE(C29:G29) -> #DIV/0!
H30: =AVERAGE(C30:G30) -> #DIV/0!
H31: =AVERAGE(C31:G31) -> #DIV/0!
H32: =AVERAGE(C32:G32) -> #DIV/0!
H33: =AVERAGE(C33:G33) -> #DIV/0!
... H37: =AVERAGE(C37:G37) -> #DIV/0!
A40: DESTAQUES DA SEMANA | H40: RISCOS E AÇÕES
A41: 1. | H41: 1.
A42: 2. | H42: 2.
A43: 3. | H43: 3.
A44: 4. | H44: 4.
A45: 5. | H45: 5.

Sheet 5 Unidades  +
D3: DASHBOARD EXECUTIVO - GRUPO DELGA
D4: Gestão Estratégica de Projetos e Redução de Custos | Grupo Delga | 2026
D6: META DO GRUPO | F6: RETORNO PREVISTO | G6: PREVISTO 2026 | H6: 💰 RETORNO VALIDADO | J6: 💰 RETORNO REAL | L6: % ATINGIMENTO DA META | N6: INICIATIVAS | P6: Top 03 Projetos (Maior Retorno REAL até o momento)
D7: =Diadema!A5+Ferraz!A5+'São Leopoldo'!A5+Jarinu!A5+Anchieta!A5+Corporativo!A5+'Compras '!A5+Vendas!A5+'Diretoria Financeira'!A5+'Head Qualidade&Dir. Industrial'!A5 -> 50320000 | F7: =SUM(E23:L23) -> 48275349 | G7: =Diadema!D5+Ferraz!D5+Anchieta!D5+'São Leopoldo'!C26+'São Leopoldo'!D5+Jarinu!C5+'Compras '!E5+Vendas!E5 -> 21759477 | H7: =Diadema!E5+Ferraz!E5+'São Leopoldo'!E5+Jarinu!E5+Anchieta!E5+Corporativo!E5+'Compras '!G5+Vendas!G5+'Diretoria Financeira'!E5+'Head Qualidade&Dir. Industrial'!E5 -> 16843792 | J7: =Diadema!G5+Ferraz!G5+Jarinu!G5+Anchieta!G5+'São Leopoldo'!G5+Vendas!I5+'Compras '!I5+Corporativo!G5 -> 4978229.6 | L7: =J7/D7 -> 0.09893143 | N7: =SUM(J13:J15) -> 204 | P7: ='Top Ganhos '!B2 -> 699813 | Q7: ='Top Ganhos '!C2 -> 08 - Reestruturação | S7: ='Top Ganhos '!D2 -> São leopoldo
P8: ='Top Ganhos '!B3 -> 570440.18 | Q8: ='Top Ganhos '!C3 -> Negociação de preços materiais carcaça Dana | S8: ='Top Ganhos '!D3 -> Compras
P9: ='Top Ganhos '!B4 -> 421900.92 | Q9: ='Top Ganhos '!C4 -> 03 - Consumo de desmoldante | S9: ='Top Ganhos '!D4 -> Ferraz
D11: 📊 SAVING ESPECULADO POR PILAR | I11: 📋 STATUS DAS INICIATIVAS | L11: 🏭 INDICADORES OPERACIONAIS | P11: MATRIZ SPD 5 unidades
D12: Pilar | E12: Qtd. | F12: Saving (R$) | G12: Saving Validado 2026 | H12: % Total | I12: Status | J12: Qtd. | K12: R$ Previsto | L12: Aderência SPD: Unidade | M12: Aderência SPD: Auditado | N12: Análise de Margem | P12: Tipo | Q12: Unidade | R12: Auditado | S12: Meta
D13: Kaizen | E13: =SUM(Diadema!B9,Ferraz!B9,'São Leopoldo'!B9,Jarinu!B9,Anchieta!B9,Corporativo!B9,'Compras '!B9,Vendas!B11,'Diretoria Financeira'!B9,'Head Qualidade&Dir. Industrial'!B9) -> 34 | F13: =SUM(Diadema!C9,Ferraz!C9,'São Leopoldo'!C9,Jarinu!C9,Anchieta!C9,Corporativo!C9,'Compras '!C9,Vendas!C11,'Diretoria Financeira'!C9,'Head Qualidade&Dir. Industrial'!C9) -> 4453440.9 | G13: =Diadema!D9+Anchieta!D9+Jarinu!D9+'São Leopoldo'!D9+Ferraz!D9+'Compras '!D9+Vendas!D11 -> 3647094.9 | H13: =G13/$G$18 -> 0.21652458 | I13: ✓ Concluído | J13: =SUM(Diadema!I9,Ferraz!I9,'São Leopoldo'!I9,Jarinu!I9,Anchieta!I9,Corporativo!H9,'Compras '!H9,Vendas!M11,'Diretoria Financeira'!H9,'Head Qualidade&Dir. Industrial'!H9) -> 67 | K13: =SUM(Diadema!J9,Ferraz!J9,'São Leopoldo'!J9,Jarinu!J9,Anchieta!J9,Corporativo!I9,'Compras '!I9,Vendas!N11,'Diretoria Financeira'!I9,'Head Qualidade&Dir. Industrial'!I9) -> 12917194 | P13: Produtividade e Controle | Q13: =SUM(Diadema!L219,Anchieta!L132,Ferraz!L144,Jarinu!L158,'São Leopoldo'!L152)/5 -> 0.9 | R13: =SUM(Diadema!M219,Anchieta!M132,Ferraz!M144,Jarinu!M158,'São Leopoldo'!M152)/5 -> 0.4 | S13: 1
D14: Redução de Custo | E14: =SUM(Diadema!B10,Ferraz!B10,'São Leopoldo'!B10,Jarinu!B10,Anchieta!B10,Corporativo!B10,'Compras '!B10,Vendas!B12,'Diretoria Financeira'!B10,'Head Qualidade&Dir. Industrial'!B10) -> 114 | F14: =SUM(Diadema!C10,Ferraz!C10,'São Leopoldo'!C10,Jarinu!C10,Anchieta!C10,Corporativo!C10,'Compras '!C10,Vendas!C12,'Diretoria Financeira'!C10,'Head Qualidade&Dir. Industrial'!C10) -> 26091797 | G14: =Diadema!D10+Anchieta!D10+Jarinu!D10+'São Leopoldo'!D10+Ferraz!D10+'Compras '!D10+Vendas!D12 -> 7567605.5 | H14: =G14/$G$18 -> 0.44928158 | I14: ⏳ Em Execução | J14: =SUM(Diadema!I10,Ferraz!I10,'São Leopoldo'!I10,Jarinu!I10,Anchieta!I10,Corporativo!H10,'Compras '!H10,Vendas!M12,'Diretoria Financeira'!H10,'Head Qualidade&Dir. Industrial'!H10) -> 125 | K14: =SUM(Diadema!J10,Ferraz!J10,'São Leopoldo'!J10,Jarinu!J10,Anchieta!J10,Corporativo!I10,'Compras '!I10,Vendas!N12,'Diretoria Financeira'!I10,'Head Qualidade&Dir. Industrial'!I10) -> 23870856 | L14: =AVERAGE(Diadema!K10,Ferraz!K10,'São Leopoldo'!K10:K11,Jarinu!K10,Anchieta!K10) -> 0.72142857 | M14: =AVERAGE(Diadema!L10,Ferraz!L10,'São Leopoldo'!L10:L11,Jarinu!L10,Anchieta!L10) -> 0.32142857 | N14: =AVERAGE(Diadema!M10,Ferraz!M10,'São Leopoldo'!M10,Jarinu!M10,Anchieta!M10) -> 0.25809246 | P14: Documentos e Registro | Q14: =SUM(Diadema!L220,Anchieta!L133,Ferraz!L145,Jarinu!L159,'São Leopoldo'!L153)/5 -> 0.8 | R14: =SUM(Diadema!M220,Anchieta!M133,Ferraz!M145,Jarinu!M159,'São Leopoldo'!M153)/5 -> 0.38333333 | S14: 1
D15: Você Resolve | E15: =SUM(Diadema!B11,Ferraz!B11,'São Leopoldo'!B11,Jarinu!B11,Anchieta!B11,Corporativo!B11,'Compras '!B11,Vendas!B13,'Diretoria Financeira'!B11,'Head Qualidade&Dir. Industrial'!B11) -> 2 | F15: =SUM(Diadema!C11,Ferraz!C11,'São Leopoldo'!C11,Jarinu!C11,Anchieta!C11,Corporativo!C11,'Compras '!C11,Vendas!C13,'Diretoria Financeira'!C11,'Head Qualidade&Dir. Industrial'!C11) -> 690000 | G15: =Diadema!D11+Anchieta!D11+Jarinu!D11+'São Leopoldo'!D11+Ferraz!D11+'Compras '!D11+Vendas!D13 -> 0 | H15: =G15/$G$18 -> 0 | I15: 📝 Não iniciado | J15: =SUM(Diadema!I11,Ferraz!I11,'São Leopoldo'!I11,Jarinu!I11,Anchieta!I11,Corporativo!H11,'Compras '!H11,Vendas!M13,'Diretoria Financeira'!H11,'Head Qualidade&Dir. Industrial'!H11) -> 12 | K15: =SUM(Diadema!J11,Ferraz!J11,'São Leopoldo'!J11,Jarinu!J11,Anchieta!J11,Corporativo!I11,'Compras '!I11,Vendas!N13,'Diretoria Financeira'!I11,'Head Qualidade&Dir. Industrial'!I11) -> 843525.14 | P15: Manutenção do Processo | Q15: =SUM(Diadema!L221,Anchieta!L134,Ferraz!L146,Jarinu!L160,'São Leopoldo'!L154)/5 -> 0.54545455 | R15: =SUM(Diadema!M221,Anchieta!M134,Ferraz!M146,Jarinu!M160,'São Leopoldo'!M154)/5 -> 0.23636364 | S15: 1
D16: BSW | E16: =SUM(Diadema!B12,Ferraz!B12,'São Leopoldo'!B12,Jarinu!B12,Anchieta!B12,Corporativo!B12,'Compras '!B12,Vendas!B14,'Diretoria Financeira'!B12,'Head Qualidade&Dir. Industrial'!B12) -> 56 | F16: =SUM(Diadema!C12,Ferraz!C12,'São Leopoldo'!C12,Jarinu!C12,Anchieta!C12,Corporativo!C12,'Compras '!C12,Vendas!C14,'Diretoria Financeira'!C12,'Head Qualidade&Dir. Industrial'!C12) -> 7044111.2 | G16: =Diadema!D12+Anchieta!D12+Jarinu!D12+'São Leopoldo'!D12+Ferraz!D12+'Compras '!D12+Vendas!D14 -> 4229091.5 | H16: =G16/$G$18 -> 0.25107717 | P16: Análise dos Dados | Q16: =SUM(Diadema!L222,Anchieta!L135,Ferraz!L147,Jarinu!L161,'São Leopoldo'!L155)/5 -> 1 | R16: =SUM(Diadema!M222,Anchieta!M135,Ferraz!M147,Jarinu!M161,'São Leopoldo'!M155)/5 -> 0.2 | S16: 1
D17: Estratégia Comercial | E17: ='Compras '!B13+Vendas!B15 -> 2 | F17: =Vendas!C15+'Compras '!C13 -> 9996000 | G17: ='Compras '!D13+Vendas!D15 -> 1400000 | H17: =G17/$G$18 -> 0.083116676
D18: TOTAL | E18: =SUM(E13:E16) -> 206 | F18: =SUM(F13:F17) -> 48275349 | G18: =SUM(G13:G17) -> 16843792 | H18: =SUM(H13:H17) -> 1
D21: - | E21: Diadema | F21: Ferraz | G21: São Leopoldo | H21: Jarinu | I21: Anchieta | J21: Corporativo | K21: Compras | L21: Vendas
D22: META DA UNIDADE | E22: =Diadema!A5 -> 6947000 | F22: =Ferraz!A5 -> 13367000 | G22: ='São Leopoldo'!A5 -> 2100000 | H22: =Jarinu!A5 -> 5356000 | I22: =Anchieta!A5 -> 3841000 | J22: =Corporativo!A5 -> 1709000 | K22: ='Compras '!A5 -> 7000000 | L22: =Vendas!A5 -> 10000000 | M22: VA | N22: =Diadema!G15+Jarinu!G15+Ferraz!G15+'São Leopoldo'!G15+Anchieta!G15+'Compras '!P17 -> 8411705.6
D23: RETORNO PREVISTO | E23: =Diadema!C5 -> 4622086.3 | F23: =Ferraz!C5 -> 7884000 | G23: ='São Leopoldo'!C5 -> 1676299.2 | H23: =Jarinu!B5 -> 3919443 | I23: =Anchieta!C5 -> 1275000 | J23: =Corporativo!C5 -> 0 | K23: ='Compras '!C5 -> 18356957 | L23: =Vendas!C5 -> 10541563 | M23: GGF | N23: =Diadema!G16+Jarinu!G16+Ferraz!G16+'São Leopoldo'!G16+Anchieta!G16+'Compras '!P18 -> 4168697.5
D24: PREVISTO (Concluido) | E24: =Diadema!J9 -> 3163136.8 | F24: =Ferraz!J9 -> 681600 | G24: ='São Leopoldo'!J9 -> 733701.5 | H24: =Jarinu!J9 -> 414120 | I24: =Anchieta!J9 -> 0 | J24: =Corporativo!I9 -> 0 | K24: ='Compras '!I9 -> 7924636 | L24: =Vendas!N11 -> 0 | M24: MA | N24: =Diadema!G17+Jarinu!G17+Ferraz!G17+'São Leopoldo'!G17+Anchieta!G17+'Compras '!P19 -> 1877825.8
D25: 💰 RETORNO VALIDADO | E25: =Diadema!E5 -> 2465004.8 | F25: =Ferraz!E5 -> 2199075.8 | G25: ='São Leopoldo'!E5 -> 2337750.5 | H25: =Jarinu!E5 -> 2819031.8 | I25: =Anchieta!E5 -> 512316.71 | J25: =Corporativo!E5 -> 0 | K25: ='Compras '!G5 -> 4565049.3 | L25: =Vendas!E5 -> 1945563 | M25: Outros | N25: =Diadema!G18+Jarinu!G18+Ferraz!G18+'São Leopoldo'!G18+Anchieta!G18+'Compras '!P20 -> 440000
D26: 💰 RETORNO REAL | E26: =Diadema!G5 -> 415214.84 | F26: =Ferraz!G5 -> 1194100.1 | G26: ='São Leopoldo'!G5 -> 821641.95 | H26: =Jarinu!G5 -> 393297.17 | I26: =Anchieta!G5 -> 141116.67 | J26: =Corporativo!G5 -> 0 | K26: ='Compras '!I5 -> 597103.47 | L26: =Vendas!G5 -> 1945563
D27: % ATINGIMENTO DA META | E27: =Diadema!J5 -> 0.059768942 | F27: =Ferraz!J5 -> 0.089331945 | G27: ='São Leopoldo'!J5 -> 0.39125807 | H27: =Jarinu!J5 -> 0.073431137 | I27: =Anchieta!J5 -> 0.036739566 | J27: =Corporativo!J5 -> 0 | K27: ='Compras '!L5 -> 0.085300496 | L27: =Vendas!J5 -> 0
D28: INICIATIVAS | E28: =Diadema!L5 -> 56 | F28: =Ferraz!L5 -> 22 | G28: ='São Leopoldo'!L5 -> 26 | H28: =Jarinu!L5 -> 34 | I28: =Anchieta!L5 -> 13 | J28: =Corporativo!M5 -> 0 | K28: ='Compras '!O5 -> 51 | L28: =Vendas!M5 -> 0
D29: Status SPD: Unidade | E29: =Diadema!K10 -> 0.64285714 | F29: =Ferraz!K10 -> 0.82142857 | G29: ='São Leopoldo'!K10 -> 0.75 | H29: =Jarinu!K10 -> 0.71428571 | I29: =Anchieta!K10 -> 0.67857143
D30: Status SPD: Auditado | E30: =Diadema!L10 -> 0.39285714 | F30: =Ferraz!L10 -> 0 | G30: ='São Leopoldo'!L10 -> 0.35714286 | H30: =Jarinu!L10 -> 0.42857143 | I30: =Anchieta!L10 -> 0.42857143
D31: Análise de Margem | E31: =N14 -> 0.25809246 | F31: =Ferraz!M10 -> 0.20833333 | G31: ='São Leopoldo'!M10 -> 0.15384615 | H31: =Jarinu!M10 -> 0.43333333 | I31: =Anchieta!M10 -> 0.33333333
F52: ,
D53: Posição | E53: Unidade / Departamento | F53: Nome do projeto /Inicio do Saving | H53: Status | I53: Status de Custos | J53: Previsto em 2026 | K53: Valor Previsto até o Momento | L53: Valor Real até o Momento | M53: Delta
D54: 1 | E54: =_xlfn.XLOOKUP(F54,Pareto!S:S,Pareto!T:T) -> Compras | F54: =_xlfn.XLOOKUP(K54,Pareto!V:V,Pareto!S:S) -> Negociação de preços materiais carcaça Dana | H54: =_xlfn.XLOOKUP(F54,Pareto!S:S,Pareto!X:X) -> ✓ Concluído | I54: =_xlfn.XLOOKUP('5 Unidades +'!F54,Pareto!S:S,Pareto!Z:Z) -> OK | J54: =_xlfn.XLOOKUP(F54,Pareto!S:S,Pareto!U:U) -> 2430268.8 | K54: =IFERROR(LARGE(Pareto!V:V,'5 Unidades +'!D54),"0") -> 1104667.6 | L54: =_xlfn.XLOOKUP(F54,Pareto!S:S,Pareto!W:W) -> 570440.18 | M54: =IF(L54="",-K54,L54-K54) -> -534227.45
D55: 2 | E55: =_xlfn.XLOOKUP(F55,Pareto!S:S,Pareto!T:T) -> São leopoldo | F55: =_xlfn.XLOOKUP(K55,Pareto!V:V,Pareto!S:S) -> 08 - Reestruturação | H55: =_xlfn.XLOOKUP(F55,Pareto!S:S,Pareto!X:X) -> ✓ Concluído | I55: =_xlfn.XLOOKUP('5 Unidades +'!F55,Pareto!S:S,Pareto!Z:Z) -> OK | J55: =_xlfn.XLOOKUP(F55,Pareto!S:S,Pareto!U:U) -> 520985.23 | K55: =IFERROR(LARGE(Pareto!V:V,D55)," ") -> 520985.23 | L55: =_xlfn.XLOOKUP(F55,Pareto!S:S,Pareto!W:W) -> 699813 | M55: =IF(L55="",-K55,L55-K55) -> 178827.77
D56: 3 | E56: =_xlfn.XLOOKUP(F56,Pareto!S:S,Pareto!T:T) -> Jarinu | F56: =_xlfn.XLOOKUP(K56,Pareto!V:V,Pareto!S:S) -> 36 - Venda Robos | H56: =_xlfn.XLOOKUP(F56,Pareto!S:S,Pareto!X:X) -> ✓ Concluído | I56: =_xlfn.XLOOKUP('5 Unidades +'!F56,Pareto!S:S,Pareto!Z:Z) -> OK | J56: =_xlfn.XLOOKUP(F56,Pareto!S:S,Pareto!U:U) -> 0 | K56: =IFERROR(LARGE(Pareto!V:V,D56)," ") -> 390000 | L56: =_xlfn.XLOOKUP(F56,Pareto!S:S,Pareto!W:W) -> 390000 | M56: =IF(L56="",-K56,L56-K56) -> -0.003
D57: 4 | E57: =_xlfn.XLOOKUP(F57,Pareto!S:S,Pareto!T:T) -> Ferraz | F57: =_xlfn.XLOOKUP(K57,Pareto!V:V,Pareto!S:S) -> 06 - Reaproveitamento de lixas | H57: =_xlfn.XLOOKUP(F57,Pareto!S:S,Pareto!X:X) -> ✓ Concluído | I57: =_xlfn.XLOOKUP('5 Unidades +'!F57,Pareto!S:S,Pareto!Z:Z) -> OK | J57: =_xlfn.XLOOKUP(F57,Pareto!S:S,Pareto!U:U) -> 151815.13 | K57: =IFERROR(LARGE(Pareto!V:V,D57)," ") -> 253025.22 | L57: =_xlfn.XLOOKUP(F57,Pareto!S:S,Pareto!W:W) -> 276395.48 | M57: =IF(L57="",-K57,L57-K57) -> 23370.263
D58: 5 | E58: =_xlfn.XLOOKUP(F58,Pareto!S:S,Pareto!T:T) -> Ferraz | F58: =_xlfn.XLOOKUP(K58,Pareto!V:V,Pareto!S:S) -> 03 - Consumo de desmoldante | H58: =_xlfn.XLOOKUP(F58,Pareto!S:S,Pareto!X:X) -> ⏳ Em Execução | I58: =_xlfn.XLOOKUP('5 Unidades +'!F58,Pareto!S:S,Pareto!Z:Z) -> OK | J58: =_xlfn.XLOOKUP(F58,Pareto!S:S,Pareto!U:U) -> 126310.64 | K58: =IFERROR(LARGE(Pareto!V:V,D58)," ") -> 210517.73 | L58: =_xlfn.XLOOKUP(F58,Pareto!S:S,Pareto!W:W) -> 421900.92 | M58: =IF(L58="",-K58,L58-K58) -> 211383.19
D59: 6 | E59: =_xlfn.XLOOKUP(F59,Pareto!S:S,Pareto!T:T) -> Ferraz | F59: =_xlfn.XLOOKUP(K59,Pareto!V:V,Pareto!S:S) -> 07 - Consumo de gás | H59: =_xlfn.XLOOKUP(F59,Pareto!S:S,Pareto!X:X) -> ⏳ Em Execução | I59: =_xlfn.XLOOKUP('5 Unidades +'!F59,Pareto!S:S,Pareto!Z:Z) -> OK | J59: =_xlfn.XLOOKUP(F59,Pareto!S:S,Pareto!U:U) -> 101344.25 | K59: =IFERROR(LARGE(Pareto!V:V,D59)," ") -> 168907.08 | L59: =_xlfn.XLOOKUP(F59,Pareto!S:S,Pareto!W:W) -> 413825.57 | M59: =IF(L59="",-K59,L59-K59) -> 244918.49 | P59: ,
D60: 7 | E60: =_xlfn.XLOOKUP(F60,Pareto!S:S,Pareto!T:T) -> Diadema | F60: =_xlfn.XLOOKUP(K60,Pareto!V:V,Pareto!S:S) -> 29 - DA000489Z_DA000490Z - STC Scania M_ | H60: =_xlfn.XLOOKUP(F60,Pareto!S:S,Pareto!X:X) -> ✓ Concluído | I60: =_xlfn.XLOOKUP('5 Unidades +'!F60,Pareto!S:S,Pareto!Z:Z) -> OK | J60: =_xlfn.XLOOKUP(F60,Pareto!S:S,Pareto!U:U) -> 446423.79 | K60: =IFERROR(LARGE(Pareto!V:V,D60)," ") -> 133927.14 | L60: =_xlfn.XLOOKUP(F60,Pareto!S:S,Pareto!W:W) -> 182981.18 | M60: =IF(L60="",-K60,L60-K60) -> 49054.041
D61: 8 | E61: =_xlfn.XLOOKUP(F61,Pareto!S:S,Pareto!T:T) -> Ferraz | F61: =_xlfn.XLOOKUP(K61,Pareto!V:V,Pareto!S:S) -> Consumo de água | H61: =_xlfn.XLOOKUP(F61,Pareto!S:S,Pareto!X:X) -> ⏳ Em Execução | I61: =_xlfn.XLOOKUP('5 Unidades +'!F61,Pareto!S:S,Pareto!Z:Z) -> OK | J61: =_xlfn.XLOOKUP(F61,Pareto!S:S,Pareto!U:U) -> 76753.75 | K61: =IFERROR(LARGE(Pareto!V:V,D61)," ") -> 127922.92 | L61: =_xlfn.XLOOKUP(F61,Pareto!S:S,Pareto!W:W) -> 45098 | M61: =IF(L61="",-K61,L61-K61) -> -82824.917
D62: 9 | E62: =_xlfn.XLOOKUP(F62,Pareto!S:S,Pareto!T:T) -> São leopoldo | F62: =_xlfn.XLOOKUP(K62,Pareto!V:V,Pareto!S:S) -> 01 - Redução de Refugo | H62: =_xlfn.XLOOKUP(F62,Pareto!S:S,Pareto!X:X) -> ⏳ Em Execução | I62: =_xlfn.XLOOKUP('5 Unidades +'!F62,Pareto!S:S,Pareto!Z:Z) -> OK | J62: =_xlfn.XLOOKUP(F62,Pareto!S:S,Pareto!U:U) -> 59652.758 | K62: =IFERROR(LARGE(Pareto!V:V,D62)," ") -> 79537.011 | L62: =_xlfn.XLOOKUP(F62,Pareto!S:S,Pareto!W:W) -> 98159.34 | M62: =IF(L62="",-K62,L62-K62) -> 18622.329
D63: 10 | E63: =_xlfn.XLOOKUP(F63,Pareto!S:S,Pareto!T:T) -> Compras | F63: =_xlfn.XLOOKUP(K63,Pareto!V:V,Pareto!S:S) -> Viabilizar itens Usiminas via Gonvarri-Full Service | H63: =_xlfn.XLOOKUP(F63,Pareto!S:S,Pareto!X:X) -> ✓ Concluído | I63: =_xlfn.XLOOKUP('5 Unidades +'!F63,Pareto!S:S,Pareto!Z:Z) | J63: =_xlfn.XLOOKUP(F63,Pareto!S:S,Pareto!U:U) -> 264492.5 | K63: =IFERROR(LARGE(Pareto!V:V,D63)," ") -> 79347.75 | L63: =_xlfn.XLOOKUP(F63,Pareto!S:S,Pareto!W:W) | M63: =IF(L63="",-K63,L63-K63) -> -79347.75
D64: 11 | E64: =_xlfn.XLOOKUP(F64,Pareto!S:S,Pareto!T:T) -> Ferraz | F64: =_xlfn.XLOOKUP(K64,Pareto!V:V,Pareto!S:S) -> 10 - Consumo de energia elétrica: vazamentos de ar | H64: =_xlfn.XLOOKUP(F64,Pareto!S:S,Pareto!X:X) -> ⏳ Em Execução | I64: =_xlfn.XLOOKUP('5 Unidades +'!F64,Pareto!S:S,Pareto!Z:Z) -> OK | J64: =_xlfn.XLOOKUP(F64,Pareto!S:S,Pareto!U:U) -> 57455.182 | K64: =IFERROR(LARGE(Pareto!V:V,D64)," ") -> 76606.909 | L64: =_xlfn.XLOOKUP(F64,Pareto!S:S,Pareto!W:W) | M64: =IF(L64="",-K64,L64-K64) -> -76606.909
D65: 12 | E65: =_xlfn.XLOOKUP(F65,Pareto!S:S,Pareto!T:T) -> Anchieta | F65: =_xlfn.XLOOKUP(K65,Pareto!V:V,Pareto!S:S) -> 04 - GÁS | H65: =_xlfn.XLOOKUP(F65,Pareto!S:S,Pareto!X:X) -> ⏳ Em Execução | I65: =_xlfn.XLOOKUP('5 Unidades +'!F65,Pareto!S:S,Pareto!Z:Z) -> OK | J65: =_xlfn.XLOOKUP(F65,Pareto!S:S,Pareto!U:U) -> 84366.097 | K65: =IFERROR(LARGE(Pareto!V:V,D65)," ") -> 56244.064 | L65: =_xlfn.XLOOKUP(F65,Pareto!S:S,Pareto!W:W) -> -2790.25 | M65: =IF(L65="",-K65,L65-K65) -> -59034.314
D66: 13 | E66: =_xlfn.XLOOKUP(F66,Pareto!S:S,Pareto!T:T) -> Compras | F66: =_xlfn.XLOOKUP(K66,Pareto!V:V,Pareto!S:S) -> Resourcing Maletas Man (Mercante para Cartec) | H66: =_xlfn.XLOOKUP(F66,Pareto!S:S,Pareto!X:X) -> ✓ Concluído | I66: =_xlfn.XLOOKUP('5 Unidades +'!F66,Pareto!S:S,Pareto!Z:Z) -> Não Ok | J66: =_xlfn.XLOOKUP(F66,Pareto!S:S,Pareto!U:U) -> 183134.17 | K66: =IFERROR(LARGE(Pareto!V:V,D66)," ") -> 54940.25 | L66: =_xlfn.XLOOKUP(F66,Pareto!S:S,Pareto!W:W) | M66: =IF(L66="",-K66,L66-K66) -> -54940.25
...

Sheet Diadema
A1: DASHBOARD EXECUTIVO - UNIDADE DIADEMA
A2: Gestão Estratégica de Projetos e Redução de Custos | Grupo Delga | 2026
A4: META DA UNIDADE | C4: RETORNO PREVISTO (Total) | D4: PREVISTO 2026 | E4: 💰 RETORNO VALIDADO | G4: 💰 RETORNO REAL | J4: % ATINGIMENTO DA META | L4: INICIATIVAS | O4: TOP 20 Raking de Projetos Valorizados | AP4: dip | AQ4: perf | AU4: 2025 | AV4: 2026
A5: =Parâmetros!E5 -> 6947000 | C5: =SUM(I55:I176) -> 4622086.3 | D5: =SUMIF(Q55:Q176,"Previsto",AI55:AI176) -> 3121824.8 | E5: =SUM(N55:N176) -> 2465004.8 | G5: =SUMIF(Q55:Q176,"Real",AI55:AI176) -> 415214.84 | J5: =G5/A5 -> 0.059768942 | L5: =SUM(I9:I11) -> 56 | O5: POS | P5: Tipo | Q5: Valor Previsto Unidade | R5: Valor Previsto Custos | S5: Retorno Previsto | T5: Retorno Real até hoje | U5: Projetos | Z5: Peso | AA5: Pareto | AB5: % Previsto | AC5: % Real | AD5: Planejado | AE5: % Responsabilidade Delga | AS5: 0.3293 | AT5: 0.9228 | AW5: p | AX5: 0.9261 | AY5: 0.95
O6: {=_xlfn.SEQUENCE(20)} -> 1 | P6: =_xlfn.XLOOKUP(U6,$C$55:$C$176,$A$55:$A$176) -> BSW | Q6: =MAX(I55:I176) -> 450000.01 | R6: =_xlfn.XLOOKUP(Q6,$I$55:$I$176,$N$55:$N$176) -> 446423.79 | S6: =_xlfn.XLOOKUP(U6,$C$55:$C$176,$J$55:$J$176) -> 46082 | T6: {=SUMPRODUCT(($C$55:$C$175=U6)*(S$54:$AG$54<=TODAY())*(ISNUMBER(S$56:$AG$176)),S$56:$AG$176)} -> 182981.18 | U6: =IFERROR(HYPERLINK(INDEX($D$55:$D$176,MATCH(Q6,$I$55:$I$176,0)),INDEX($C$55:$C$176,MATCH(Q6,$I$55:$I$176,0)) ), ) -> 29 - DA000489Z_DA000490Z - STC Scania M_ | Z6: =Q6/$C$5 -> 0.097358634 | AA6: =Z6 -> 0.097358634 | AB6: {=IFERROR(INDEX($R$55:$R$176,MATCH(1,($AN$55:$AN$176=U6)*($Q$55:$Q$176="Previsto"), 0) ), "")} -> 1 | AC6: {=IFERROR( INDEX($R$55:$R$176,MATCH(1,($AN$55:$AN$176=U6)*($Q$55:$Q$176="Real"),0)),"")} -> 1 | AD6: =IF(OR(AB6="",AC6=""),"",IF(AC6=100%,"CONCLUÍDO",IF(AC6=0,IF(AB6=0,"PROJETO NÃO INICIADO","FALTA DE ACOMPANHAMENTO"),IF(AC6>AB6,"ADIANTADO",IF(AC6=AB6,"CONFORME PLANEJADO","ATRASO"))))) -> CONCLUÍDO | AE6: {=_xlfn.XLOOKUP($U$6:$U$25,$C$55:$C$176,$P$55:$P$176)} -> 1 | AS6: 0.4166 | AT6: 0.9152 | AW6: d | AX6: 0.5017 | AY6: 0.58
A7: 📊 SAVING PREVISTO POR PILAR | H7: 📋 STATUS DAS INICIATIVAS | K7: 🏭 INDICADORES OPERACIONAIS | O7: 2 | P7: =_xlfn.XLOOKUP(U7,$C$55:$C$176,$A$55:$A$176) -> BSW | Q7: =IFERROR(LARGE($I$55:$I$176,O7)," ") -> 331600 | R7: =_xlfn.XLOOKUP(Q7,$I$55:$I$176,$N$55:$N$176) -> 160178.29 | S7: =_xlfn.XLOOKUP(U7,$C$55:$C$176,$J$55:$J$176) -> 46082 | T7: {=SUMPRODUCT(($C$55:$C$175=U7)*(S$54:$AG$54<=TODAY())*(ISNUMBER(S$56:$AG$176)),S$56:$AG$176)} -> 51688.193 | U7: =IFERROR(HYPERLINK(INDEX($D$55:$D$176,MATCH(Q7,$I$55:$I$176,0)),INDEX($C$55:$C$176,MATCH(Q7,$I$55:$I$176,0)) ), "" ) -> 01 - Redução de peso bruto DA000489A | Z7: =Q7/$C$5 -> 0.071742494 | AA7: =Z7+AA6 -> 0.16910113 | AB7: {=IFERROR(INDEX($R$55:$R$176,MATCH(1,($AN$55:$AN$176=U7)*($Q$55:$Q$176="Previsto"), 0) ), "")} -> 1 | AC7: {=IFERROR( INDEX($R$55:$R$176,MATCH(1,($AN$55:$AN$176=U7)*($Q$55:$Q$176="Real"),0)),"")} -> 1 | AD7: =IF(OR(AB7="",AC7=""),"",IF(AC7=100%,"CONCLUÍDO",IF(AC7=0,IF(AB7=0,"PROJETO NÃO INICIADO","FALTA DE ACOMPANHAMENTO"),IF(AC7>AB7,"ADIANTADO",IF(AC7=AB7,"CONFORME PLANEJADO","ATRASO"))))) -> CONCLUÍDO | AE7: 1 | AS7: 0.4666 | AT7: 0.9202 | AW7: q | AX7: 0.955 | AY7: 0.965
A8: Pilar | B8: Qtd. | C8: Saving (R$) | D8: Saving Validado 2026 | E8: % Total | F8: Barra | H8: Status | I8: Qtd. | J8: R$ Previsto | K8: Aderência SPD: Unidade | L8: Aderência SPD: Auditado | M8: Análise de Margem (Form 206) | O8: 3 | P8: =_xlfn.XLOOKUP(U8,$C$55:$C$176,$A$55:$A$176) -> Redução de custo | Q8: =IFERROR(LARGE($I$55:$I$176,O8)," ") -> 288000 | R8: =_xlfn.XLOOKUP(Q8,$I$55:$I$176,$N$55:$N$176) -> 79673.52 | S8: =_xlfn.XLOOKUP(U8,$C$55:$C$176,$J$55:$J$176) -> 46143 | T8: {=SUMPRODUCT(($C$55:$C$175=U8)*(S$54:$AG$54<=TODAY())*(ISNUMBER(S$56:$AG$176)),S$56:$AG$176)} -> -31423.7 | U8: =IFERROR(HYPERLINK(INDEX($D$55:$D$176,MATCH(Q8,$I$55:$I$176,0)),INDEX($C$55:$C$176,MATCH(Q8,$I$55:$I$176,0)) ), "" ) -> 06 - Produtividade | Z8: =Q8/$C$5 -> 0.062309525 | AA8: =Z8+AA7 -> 0.23141065 | AB8: {=IFERROR(INDEX($R$55:$R$176,MATCH(1,($AN$55:$AN$176=U8)*($Q$55:$Q$176="Previsto"), 0) ), "")} -> 0.96 | AC8: {=IFERROR( INDEX($R$55:$R$176,MATCH(1,($AN$55:$AN$176=U8)*($Q$55:$Q$176="Real"),0)),"")} -> 0.98 | AD8: =IF(OR(AB8="",AC8=""),"",IF(AC8=100%,"CONCLUÍDO",IF(AC8=0,IF(AB8=0,"PROJETO NÃO INICIADO","FALTA DE ACOMPANHAMENTO"),IF(AC8>AB8,"ADIANTADO",IF(AC8=AB8,"CONFORME PLANEJADO","ATRASO"))))) -> ADIANTADO | AE8: 1 | AT8: 0.5436 | AU8: 0.9206 | AY8: =AX7*AX6*AX5 -> 0.44371627 | AZ8: =AY7*AY6*AY5 -> 0.531715
A9: Kaizen | B9: =COUNTIF($A$55:$A$176,A9) -> 10 | C9: =SUMIF($A$55:$A$176,A9,$I$55:$I$176) -> 625866.77 | D9: =SUMIF($A$55:$A$176,A9,$N$55:$N$176) -> 168076.19 | E9: =IF($D$13=0,"",D9/$D$13) -> 0.068184935 | F9: =E9 -> 0.068184935 | H9: ✓ Concluído | I9: =COUNTIF($O$55:$O$176,H9) -> 36 | J9: =SUMIF($O$55:$O$176,H9,$I$55:$I$176) -> 3163136.8 | O9: 4 | Z9: =Q9/$C$5 -> 0 | AA9: =Z9+AA8 -> 0.23141065 | AB9: {=IFERROR(INDEX($R$55:$R$176,MATCH(1,($AN$55:$AN$176=U9)*($Q$55:$Q$176="Previsto"), 0) ), "")} | AC9: {=IFERROR( INDEX($R$55:$R$176,MATCH(1,($AN$55:$AN$176=U9)*($Q$55:$Q$176="Real"),0)),"")} -> 0 | AD9: =IF(OR(AB9="",AC9=""),"",IF(AC9=100%,"CONCLUÍDO",IF(AC9=0,IF(AB9=0,"PROJETO NÃO INICIADO","FALTA DE ACOMPANHAMENTO"),IF(AC9>AB9,"ADIANTADO",IF(AC9=AB9,"CONFORME PLANEJADO","ATRASO"))))) | AE9: 0 | AT9: 0.5123 | AU9: 0.923
A10: Redução de Custo | B10: =COUNTIF($A$55:$A$176,A10) -> 10 | C10: =SUMIF($A$55:$A$176,A10,$I$55:$I$176) -> 592471.54 | D10: =SUMIF($A$55:$A$176,A10,$N$55:$N$176) -> 208784.28 | E10: =IF($D$13=0,"",D10/$D$13) -> 0.084699341 | F10: =E10 -> 0.084699341 | H10: ⏳ Em Execução | I10: =COUNTIF($O$55:$O$176,H10) -> 19 | J10: =SUMIF($O$55:$O$176,H10,$I$55:$I$176) -> 1458948 | K10: =E207 -> 0.64285714 | L10: =F207 -> 0.39285714 | M10: =L214 -> 0.16161616 | O10: 5 | P10: =_xlfn.XLOOKUP(U10,$C$55:$C$176,$A$55:$A$176) -> BSW | Q10: =IFERROR(LARGE($I$55:$I$176,O10)," ") -> 270000 | R10: =_xlfn.XLOOKUP(Q10,$I$55:$I$176,$N$55:$N$176) -> 128107.04 | S10: =_xlfn.XLOOKUP(U10,$C$55:$C$176,$J$55:$J$176) -> 46174 | T10: {=SUMPRODUCT(($C$55:$C$175=U10)*(S$54:$AG$54<=TODAY())*(ISNUMBER(S$56:$AG$176)),S$56:$AG$176)} -> 0 | U10: =IFERROR(HYPERLINK(INDEX($D$55:$D$176,MATCH(Q10,$I$55:$I$176,0)),INDEX($C$55:$C$176,MATCH(Q10,$I$55:$I$176,0)) ), "" ) -> 23 - Redução do peso bruto VW000581Z / VW000582Z | Z10: =Q10/$C$5 -> 0.058415179 | AA10: =Z10+AA9 -> 0.28982583 | AB10: {=IFERROR(INDEX($R$55:$R$176,MATCH(1,($AN$55:$AN$176=U10)*($Q$55:$Q$176="Previsto"), 0) ), "")} -> 0.2 | AC10: {=IFERROR( INDEX($R$55:$R$176,MATCH(1,($AN$55:$AN$176=U10)*($Q$55:$Q$176="Real"),0)),"")} -> 0.25 | AD10: =IF(OR(AB10="",AC10=""),"",IF(AC10=100%,"CONCLUÍDO",IF(AC10=0,IF(AB10=0,"PROJETO NÃO INICIADO","FALTA DE ACOMPANHAMENTO"),IF(AC10>AB10,"ADIANTADO",IF(AC10=AB10,"CONFORME PLANEJADO","ATRASO"))))) -> ADIANTADO | AE10: 0.8 | AT10: 0.5216 | AU10: 0.9165
A11: Você Resolve | B11: =COUNTIF($A$55:$A$176,A11) -> 0 | C11: =SUMIF($A$55:$A$176,A11,$I$55:$I$176) -> 0 | D11: =SUMIF($A$55:$A$176,A11,$N$55:$N$176) -> 0 | E11: =IF($D$13=0,"",D11/$D$13) -> 0 | F11: =E11 -> 0 | H11: 📝 Não iniciado | I11: =COUNTIF($O$55:$O$176,H11) -> 1 | J11: =SUMIF($O$55:$O$176,H11,$I$55:$I$176) -> 1.5355 | O11: 6 | P11: =_xlfn.XLOOKUP(U11,$C$55:$C$176,$A$55:$A$176) -> BSW | Q11: =IFERROR(LARGE($I$55:$I$176,O11)," ") -> 236000 | R11: =_xlfn.XLOOKUP(Q11,$I$55:$I$176,$N$55:$N$176) -> 138092.84 | S11: =_xlfn.XLOOKUP(U11,$C$55:$C$176,$J$55:$J$176) -> 46174 | T11: {=SUMPRODUCT(($C$55:$C$175=U11)*(S$54:$AG$54<=TODAY())*(ISNUMBER(S$56:$AG$176)),S$56:$AG$176)} -> 0 | U11: =IFERROR(HYPERLINK(INDEX($D$55:$D$176,MATCH(Q11,$I$55:$I$176,0)),INDEX($C$55:$C$176,MATCH(Q11,$I$55:$I$176,0)) ), "" ) -> 52 - Redução de MP - GM000458Z / GM000459Z | Z11: =Q11/$C$5 -> 0.051059194 | AA11: =Z11+AA10 -> 0.34088503 | AB11: {=IFERROR(INDEX($R$55:$R$176,MATCH(1,($AN$55:$AN$176=U11)*($Q$55:$Q$176="Previsto"), 0) ), "")} -> 1 | AC11: {=IFERROR( INDEX($R$55:$R$176,MATCH(1,($AN$55:$AN$176=U11)*($Q$55:$Q$176="Real"),0)),"")} -> 1 | AD11: =IF(OR(AB11="",AC11=""),"",IF(AC11=100%,"CONCLUÍDO",IF(AC11=0,IF(AB11=0,"PROJETO NÃO INICIADO","FALTA DE ACOMPANHAMENTO"),IF(AC11>AB11,"ADIANTADO",IF(AC11=AB11,"CONFORME PLANEJADO","ATRASO"))))) -> CONCLUÍDO | AE11: 1 | AT11: 0.5217 | AU11: 0.9237
A12: BSW | B12: =COUNTIF($A$55:$A$176,A12) -> 37 | C12: =SUMIF($A$55:$A$176,A12,$I$55:$I$176) -> 3403748 | D12: =SUMIF($A$55:$A$176,A12,$N$55:$N$176) -> 2088144.3 | E12: =IF($D$13=0,"",D12/$D$13) -> 0.84711572 | F12: =E12 -> 0.84711572 | O12: 7 | P12: =_xlfn.XLOOKUP(U12,$C$55:$C$176,$A$55:$A$176) -> BSW | Q12: =IFERROR(LARGE($I$55:$I$176,O12)," ") -> 230000 | R12: =_xlfn.XLOOKUP(Q12,$I$55:$I$176,$N$55:$N$176) -> 115000 | S12: =_xlfn.XLOOKUP(U12,$C$55:$C$176,$J$55:$J$176) -> 46204 | T12: {=SUMPRODUCT(($C$55:$C$175=U12)*(S$54:$AG$54<=TODAY())*(ISNUMBER(S$56:$AG$176)),S$56:$AG$176)} -> 0 | U12: =IFERROR(HYPERLINK(INDEX($D$55:$D$176,MATCH(Q12,$I$55:$I$176,0)),INDEX($C$55:$C$176,MATCH(Q12,$I$55:$I$176,0)) ), "" ) -> 44 - Mudança de fonte Usiminas para Arcelor | Z12: =Q12/$C$5 -> 0.049761078 | AA12: =Z12+AA11 -> 0.3906461 | AB12: {=IFERROR(INDEX($R$55:$R$176,MATCH(1,($AN$55:$AN$176=U12)*($Q$55:$Q$176="Previsto"), 0) ), "")} -> 0.29 | AC12: {=IFERROR( INDEX($R$55:$R$176,MATCH(1,($AN$55:$AN$176=U12)*($Q$55:$Q$176="Real"),0)),"")} -> 0.36 | AD12: =IF(OR(AB12="",AC12=""),"",IF(AC12=100%,"CONCLUÍDO",IF(AC12=0,IF(AB12=0,"PROJETO NÃO INICIADO","FALTA DE ACOMPANHAMENTO"),IF(AC12>AB12,"ADIANTADO",IF(AC12=AB12,"CONFORME PLANEJADO","ATRASO"))))) -> ADIANTADO | AE12: 0.2 | AT12: 0.5746 | AU12: 0.936
A13: TOTAL | B13: =SUM(B9:B12) -> 57 | C13: =SUM(C9:C12) -> 4622086.3 | D13: =SUM(D9:D12) -> 2465004.8 | E13: =SUM(E9:E12) -> 1 | O13: 8 | P13: =_xlfn.XLOOKUP(U13,$C$55:$C$176,$A$55:$A$176) -> Kaizen | Q13: =IFERROR(LARGE($I$55:$I$176,O13)," ") -> 228000 | R13: =_xlfn.XLOOKUP(Q13,$I$55:$I$176,$N$55:$N$176) -> 124710.19 | S13: =_xlfn.XLOOKUP(U13,$C$55:$C$176,$J$55:$J$176) -> 46082 | T13: {=SUMPRODUCT(($C$55:$C$175=U13)*(S$54:$AG$54<=TODAY())*(ISNUMBER(S$56:$AG$176)),S$56:$AG$176)} -> 12885.19 | U13: =IFERROR(HYPERLINK(INDEX($D$55:$D$176,MATCH(Q13,$I$55:$I$176,0)),INDEX($C$55:$C$176,MATCH(Q13,$I$55:$I$176,0)) ), "" ) -> 16 - Eficiência de MO na linha de Solda e Montagem | Z13: =Q13/$C$5 -> 0.049328373 | AA13: =Z13+AA12 -> 0.43997448 | AB13: {=IFERROR(INDEX($R$55:$R$176,MATCH(1,($AN$55:$AN$176=U13)*($Q$55:$Q$176="Previsto"), 0) ), "")} -> 1 | AC13: {=IFERROR( INDEX($R$55:$R$176,MATCH(1,($AN$55:$AN$176=U13)*($Q$55:$Q$176="Real"),0)),"")} -> 1 | AD13: =IF(OR(AB13="",AC13=""),"",IF(AC13=100%,"CONCLUÍDO",IF(AC13=0,IF(AB13=0,"PROJETO NÃO INICIADO","FALTA DE ACOMPANHAMENTO"),IF(AC13>AB13,"ADIANTADO",IF(AC13=AB13,"CONFORME PLANEJADO","ATRASO"))))) -> CONCLUÍDO | AE13: 1 | AT13: 0.5423 | AU13: 0.936
O14: 9 | P14: =_xlfn.XLOOKUP(U14,$C$55:$C$176,$A$55:$A$176) -> BSW | Q14: =IFERROR(LARGE($I$55:$I$176,O14)," ") -> 223200 | R14: =_xlfn.XLOOKUP(Q14,$I$55:$I$176,$N$55:$N$176) -> 0 | S14: =_xlfn.XLOOKUP(U14,$C$55:$C$176,$J$55:$J$176) -> 46174 | T14: {=SUMPRODUCT(($C$55:$C$175=U14)*(S$54:$AG$54<=TODAY())*(ISNUMBER(S$56:$AG$176)),S$56:$AG$176)} -> 0 | U14: =IFERROR(HYPERLINK(INDEX($D$55:$D$176,MATCH(Q14,$I$55:$I$176,0)),INDEX($C$55:$C$176,MATCH(Q14,$I$55:$I$176,0)) ), "" ) -> 57 - AlmaCAM_Redução de Peso | Z14: =Q14/$C$5 -> 0.048289881 | AA14: =Z14+AA13 -> 0.48826436 | AB14: {=IFERROR(INDEX($R$55:$R$176,MATCH(1,($AN$55:$AN$176=U14)*($Q$55:$Q$176="Previsto"), 0) ), "")} -> 1 | AC14: {=IFERROR( INDEX($R$55:$R$176,MATCH(1,($AN$55:$AN$176=U14)*($Q$55:$Q$176="Real"),0)),"")} -> 1 | AD14: =IF(OR(AB14="",AC14=""),"",IF(AC14=100%,"CONCLUÍDO",IF(AC14=0,IF(AB14=0,"PROJETO NÃO INICIADO","FALTA DE ACOMPANHAMENTO"),IF(AC14>AB14,"ADIANTADO",IF(AC14=AB14,"CONFORME PLANEJADO","ATRASO"))))) -> CONCLUÍDO | AE14: 1 | AS14: 0.5472 | AT14: 0.9115
F15: VA | G15: =SUMIF($B$55:$B$176,F15,$N$55:$N$176) -> 2088144.3 | O15: 10 | P15: =_xlfn.XLOOKUP(U15,$C$55:$C$176,$A$55:$A$176) -> BSW | Q15: =IFERROR(LARGE($I$55:$I$176,O15)," ") -> 189200 | R15: =_xlfn.XLOOKUP(Q15,$I$55:$I$176,$N$55:$N$176) -> 70963.59 | S15: =_xlfn.XLOOKUP(U15,$C$55:$C$176,$J$55:$J$176) -> 46235 | T15: {=SUMPRODUCT(($C$55:$C$175=U15)*(S$54:$AG$54<=TODAY())*(ISNUMBER(S$56:$AG$176)),S$56:$AG$176)} -> 0 | U15: =IFERROR(HYPERLINK(INDEX($D$55:$D$176,MATCH(Q15,$I$55:$I$176,0)),INDEX($C$55:$C$176,MATCH(Q15,$I$55:$I$176,0)) ), "" ) -> 47 - REDUÇÃO DE MP DJ000079Z – 80Z | Z15: =Q15/$C$5 -> 0.040933896 | AA15: =Z15+AA14 -> 0.52919825 | AB15: {=IFERROR(INDEX($R$55:$R$176,MATCH(1,($AN$55:$AN$176=U15)*($Q$55:$Q$176="Previsto"), 0) ), "")} -> 0.24 | AC15: {=IFERROR( INDEX($R$55:$R$176,MATCH(1,($AN$55:$AN$176=U15)*($Q$55:$Q$176="Real"),0)),"")} -> 0.38 | AD15: =IF(OR(AB15="",AC15=""),"",IF(AC15=100%,"CONCLUÍDO",IF(AC15=0,IF(AB15=0,"PROJETO NÃO INICIADO","FALTA DE ACOMPANHAMENTO"),IF(AC15>AB15,"ADIANTADO",IF(AC15=AB15,"CONFORME PLANEJADO","ATRASO"))))) -> ADIANTADO | AE15: 0.5 | AS15: 0.5483 | AT15: 0.9229
F16: GGF | G16: =SUMIF($B$55:$B$176,F16,$N$55:$N$176) -> 376860.47 | O16: 11 | P16: =_xlfn.XLOOKUP(U16,$C$55:$C$176,$A$55:$A$176) -> Redução de custo | Q16: =IFERROR(LARGE($I$55:$I$176,O16)," ") -> 160000 | R16: =_xlfn.XLOOKUP(Q16,$I$55:$I$176,$N$55:$N$176) -> 72500 | S16: =_xlfn.XLOOKUP(U16,$C$55:$C$176,$J$55:$J$176) -> 46174 | T16: {=SUMPRODUCT(($C$55:$C$175=U16)*(S$54:$AG$54<=TODAY())*(ISNUMBER(S$56:$AG$176)),S$56:$AG$176)} -> 0 | U16: =IFERROR(HYPERLINK(INDEX($D$55:$D$176,MATCH(Q16,$I$55:$I$176,0)),INDEX($C$55:$C$176,MATCH(Q16,$I$55:$I$176,0)) ), "" ) -> 42 - Aluguel de Compressor | Z16: =Q16/$C$5 -> 0.034616402 | AA16: =Z16+AA15 -> 0.56381466 | AB16: {=IFERROR(INDEX($R$55:$R$176,MATCH(1,($AN$55:$AN$176=U16)*($Q$55:$Q$176="Previsto"), 0) ), "")} -> 0.43 | AC16: {=IFERROR( INDEX($R$55:$R$176,MATCH(1,($AN$55:$AN$176=U16)*($Q$55:$Q$176="Real"),0)),"")} -> 1 | AD16: =IF(OR(AB16="",AC16=""),"",IF(AC16=100%,"CONCLUÍDO",IF(AC16=0,IF(AB16=0,"PROJETO NÃO INICIADO","FALTA DE ACOMPANHAMENTO"),IF(AC16>AB16,"ADIANTADO",IF(AC16=AB16,"CONFORME PLANEJADO","ATRASO"))))) -> CONCLUÍDO | AE16: 1 | AS16: 0.4958 | AT16: 0.9642
F17: MA | G17: =SUMIF($B$55:$B$176,F17,$N$55:$N$176) -> 0 | O17: 12 | P17: =_xlfn.XLOOKUP(U17,$C$55:$C$176,$A$55:$A$176) -> Kaizen | Q17: =IFERROR(LARGE($I$55:$I$176,O17)," ") -> 135186 | R17: =_xlfn.XLOOKUP(Q17,$I$55:$I$176,$N$55:$N$176) -> 0 | S17: =_xlfn.XLOOKUP(U17,$C$55:$C$176,$J$55:$J$176) -> 0 | T17: {=SUMPRODUCT(($C$55:$C$175=U17)*(S$54:$AG$54<=TODAY())*(ISNUMBER(S$56:$AG$176)),S$56:$AG$176)} -> 0 | U17: =IFERROR(HYPERLINK(INDEX($D$55:$D$176,MATCH(Q17,$I$55:$I$176,0)),INDEX($C$55:$C$176,MATCH(Q17,$I$55:$I$176,0)) ), "" ) -> 02 - Redução na quantidade de lâmpadas acessa, na produção | Z17: =Q17/$C$5 -> 0.029247831 | AA17: =Z17+AA16 -> 0.59306249 | AB17: {=IFERROR(INDEX($R$55:$R$176,MATCH(1,($AN$55:$AN$176=U17)*($Q$55:$Q$176="Previsto"), 0) ), "")} -> 1 | AC17: {=IFERROR( INDEX($R$55:$R$176,MATCH(1,($AN$55:$AN$176=U17)*($Q$55:$Q$176="Real"),0)),"")} -> 1 | AD17: =IF(OR(AB17="",AC17=""),"",IF(AC17=100%,"CONCLUÍDO",IF(AC17=0,IF(AB17=0,"PROJETO NÃO INICIADO","FALTA DE ACOMPANHAMENTO"),IF(AC17>AB17,"ADIANTADO",IF(AC17=AB17,"CONFORME PLANEJADO","ATRASO"))))) -> CONCLUÍDO | AE17: 1 | AS17: =AVERAGE(AS5:AS16) -> 0.4673 | AT17: =AVERAGE(AT5:AT16) -> 0.731075 | AU17: =AT17*AS17 -> 0.34163135
F18: Outros | G18: =SUMIF($B$55:$B$176,F18,$N$55:$N$176) -> 0 | O18: 13 | P18: =_xlfn.XLOOKUP(U18,$C$55:$C$176,$A$55:$A$176) -> BSW | Q18: =IFERROR(LARGE($I$55:$I$176,O18)," ") -> 115000 | R18: =_xlfn.XLOOKUP(Q18,$I$55:$I$176,$N$55:$N$176) -> 39111.77 | S18: =_xlfn.XLOOKUP(U18,$C$55:$C$176,$J$55:$J$176) -> 46174 | T18: {=SUMPRODUCT(($C$55:$C$175=U18)*(S$54:$AG$54<=TODAY())*(ISNUMBER(S$56:$AG$176)),S$56:$AG$176)} -> 0 | U18: =IFERROR(HYPERLINK(INDEX($D$55:$D$176,MATCH(Q18,$I$55:$I$176,0)),INDEX($C$55:$C$176,MATCH(Q18,$I$55:$I$176,0)) ), "" ) -> 30 - DA000491Z_DE000492Z - STC Scania G_ | Z18: =Q18/$C$5 -> 0.024880539 | AA18: =Z18+AA17 -> 0.61794303 | AB18: {=IFERROR(INDEX($R$55:$R$176,MATCH(1,($AN$55:$AN$176=U18)*($Q$55:$Q$176="Previsto"), 0) ), "")} -> 1 | AC18: {=IFERROR( INDEX($R$55:$R$176,MATCH(1,($AN$55:$AN$176=U18)*($Q$55:$Q$176="Real"),0)),"")} -> 0.95 | AD18: =IF(OR(AB18="",AC18=""),"",IF(AC18=100%,"CONCLUÍDO",IF(AC18=0,IF(AB18=0,"PROJETO NÃO INICIADO","FALTA DE ACOMPANHAMENTO"),IF(AC18>AB18,"ADIANTADO",IF(AC18=AB18,"CONFORME PLANEJADO","ATRASO"))))) -> ATRASO | AE18: 1
O19: 14 | P19: =_xlfn.XLOOKUP(U19,$C$55:$C$176,$A$55:$A$176) -> BSW | Q19: =IFERROR(LARGE($I$55:$I$176,O19)," ") -> 106000 | R19: =_xlfn.XLOOKUP(Q19,$I$55:$I$176,$N$55:$N$176) -> 99381.26 | S19: =_xlfn.XLOOKUP(U19,$C$55:$C$176,$J$55:$J$176) -> 46136 | T19: {=SUMPRODUCT(($C$55:$C$175=U19)*(S$54:$AG$54<=TODAY())*(ISNUMBER(S$56:$AG$176)),S$56:$AG$176)} -> 34660.772 | U19: =IFERROR(HYPERLINK(INDEX($D$55:$D$176,MATCH(Q19,$I$55:$I$176,0)),INDEX($C$55:$C$176,MATCH(Q19,$I$55:$I$176,0)) ), "" ) -> 45 - Redução de MP GM000409Z | Z19: =Q19/$C$5 -> 0.022933367 | AA19: =Z19+AA18 -> 0.64087639 | AB19: {=IFERROR(INDEX($R$55:$R$176,MATCH(1,($AN$55:$AN$176=U19)*($Q$55:$Q$176="Previsto"), 0) ), "")} -> 0.88 | AC19: {=IFERROR( INDEX($R$55:$R$176,MATCH(1,($AN$55:$AN$176=U19)*($Q$55:$Q$176="Real"),0)),"")} -> 0.97 | AD19: =IF(OR(AB19="",AC19=""),"",IF(AC19=100%,"CONCLUÍDO",IF(AC19=0,IF(AB19=0,"PROJETO NÃO INICIADO","FALTA DE ACOMPANHAMENTO"),IF(AC19>AB19,"ADIANTADO",IF(AC19=AB19,"CONFORME PLANEJADO","ATRASO"))))) -> ADIANTADO | AE19: 1
O20: 15 | P20: =_xlfn.XLOOKUP(U20,$C$55:$C$176,$A$55:$A$176) -> Kaizen | Q20: =IFERROR(LARGE($I$55:$I$176,O20)," ") -> 96000 | R20: =_xlfn.XLOOKUP(Q20,$I$55:$I$176,$N$55:$N$176) -> 0 | S20: =_xlfn.XLOOKUP(U20,$C$55:$C$176,$J$55:$J$176) -> 46204 | T20: {=SUMPRODUCT(($C$55:$C$175=U20)*(S$54:$AG$54<=TODAY())*(ISNUMBER(S$56:$AG$176)),S$56:$AG$176)} -> 0 | U20: =IFERROR(HYPERLINK(INDEX($D$55:$D$176,MATCH(Q20,$I$55:$I$176,0)),INDEX($C$55:$C$176,MATCH(Q20,$I$55:$I$176,0)) ), "" ) -> 43 - Automação Boomerang | Z20: =Q20/$C$5 -> 0.020769841 | AA20: =Z20+AA19 -> 0.66164623 | AB20: {=IFERROR(INDEX($R$55:$R$176,MATCH(1,($AN$55:$AN$176=U20)*($Q$55:$Q$176="Previsto"), 0) ), "")} -> 0.3 | AC20: {=IFERROR( INDEX($R$55:$R$176,MATCH(1,($AN$55:$AN$176=U20)*($Q$55:$Q$176="Real"),0)),"")} -> 0.32 | AD20: =IF(OR(AB20="",AC20=""),"",IF(AC20=100%,"CONCLUÍDO",IF(AC20=0,IF(AB20=0,"PROJETO NÃO INICIADO","FALTA DE ACOMPANHAMENTO"),IF(AC20>AB20,"ADIANTADO",IF(AC20=AB20,"CONFORME PLANEJADO","ATRASO"))))) -> ADIANTADO | AE20: 1
O21: 16 | P21: =_xlfn.XLOOKUP(U21,$C$55:$C$176,$A$55:$A$176) -> BSW | Q21: =IFERROR(LARGE($I$55:$I$176,O21)," ") -> 92500 | R21: =_xlfn.XLOOKUP(Q21,$I$55:$I$176,$N$55:$N$176) -> 153302.58 | S21: =_xlfn.XLOOKUP(U21,$C$55:$C$176,$J$55:$J$176) -> 46174 | T21: {=SUMPRODUCT(($C$55:$C$175=U21)*(S$54:$AG$54<=TODAY())*(ISNUMBER(S$56:$AG$176)),S$56:$AG$176)} -> 0 | U21: =IFERROR(HYPERLINK(INDEX($D$55:$D$176,MATCH(Q21,$I$55:$I$176,0)),INDEX($C$55:$C$176,MATCH(Q21,$I$55:$I$176,0)) ), "" ) -> 50 - Suporte da lanterna MB003681 | Z21: =Q21/$C$5 -> 0.020012608 | AA21: =Z21+AA20 -> 0.68165884 | AB21: {=IFERROR(INDEX($R$55:$R$176,MATCH(1,($AN$55:$AN$176=U21)*($Q$55:$Q$176="Previsto"), 0) ), "")} -> 0.86 | AC21: {=IFERROR( INDEX($R$55:$R$176,MATCH(1,($AN$55:$AN$176=U21)*($Q$55:$Q$176="Real"),0)),"")} -> 0.86 | AD21: =IF(OR(AB21="",AC21=""),"",IF(AC21=100%,"CONCLUÍDO",IF(AC21=0,IF(AB21=0,"PROJETO NÃO INICIADO","FALTA DE ACOMPANHAMENTO"),IF(AC21>AB21,"ADIANTADO",IF(AC21=AB21,"CONFORME PLANEJADO","ATRASO"))))) -> CONFORME PLANEJADO | AE21: 1
O22: 17 | P22: =_xlfn.XLOOKUP(U22,$C$55:$C$176,$A$55:$A$176) -> BSW | Q22: =IFERROR(LARGE($I$55:$I$176,O22)," ") -> 91200 | R22: =_xlfn.XLOOKUP(Q22,$I$55:$I$176,$N$55:$N$176) -> 28666.41 | S22: =_xlfn.XLOOKUP(U22,$C$55:$C$176,$J$55:$J$176) -> 46204 | T22: {=SUMPRODUCT(($C$55:$C$175=U22)*(S$54:$AG$54<=TODAY())*(ISNUMBER(S$56:$AG$176)),S$56:$AG$176)} -> 0 | U22: =IFERROR(HYPERLINK(INDEX($D$55:$D$176,MATCH(Q22,$I$55:$I$176,0)),INDEX($C$55:$C$176,MATCH(Q22,$I$55:$I$176,0)) ), "" ) -> 56 -Redução de Peso Bruto do item SV001141LA / SV001142LA | Z22: =Q22/$C$5 -> 0.019731349 | AA22: =Z22+AA21 -> 0.70139019 | AB22: {=IFERROR(INDEX($R$55:$R$176,MATCH(1,($AN$55:$AN$176=U22)*($Q$55:$Q$176="Previsto"), 0) ), "")} -> 0.86792453 | AC22: {=IFERROR( INDEX($R$55:$R$176,MATCH(1,($AN$55:$AN$176=U22)*($Q$55:$Q$176="Real"),0)),"")} -> 0.75 | AD22: =IF(OR(AB22="",AC22=""),"",IF(AC22=100%,"CONCLUÍDO",IF(AC22=0,IF(AB22=0,"PROJETO NÃO INICIADO","FALTA DE ACOMPANHAMENTO"),IF(AC22>AB22,"ADIANTADO",IF(AC22=AB22,"CONFORME PLANEJADO","ATRASO"))))) -> ATRASO | AE22: 1
O23: 18 | P23: =_xlfn.XLOOKUP(U23,$C$55:$C$176,$A$55:$A$176) -> BSW | Q23: =IFERROR(LARGE($I$55:$I$176,O23)," ") -> 90000 | R23: =_xlfn.XLOOKUP(Q23,$I$55:$I$176,$N$55:$N$176) -> 41632.63 | S23: =_xlfn.XLOOKUP(U23,$C$55:$C$176,$J$55:$J$176) -> 46174 | T23: {=SUMPRODUCT(($C$55:$C$175=U23)*(S$54:$AG$54<=TODAY())*(ISNUMBER(S$56:$AG$176)),S$56:$AG$176)} -> 0 | U23: =IFERROR(HYPERLINK(INDEX($D$55:$D$176,MATCH(Q23,$I$55:$I$176,0)),INDEX($C$55:$C$176,MATCH(Q23,$I$55:$I$176,0)) ), "" ) -> 27 - DA000459AA - STC Volvo_ | Z23: =Q23/$C$5 -> 0.019471726 | AA23: =Z23+AA22 -> 0.72086192 | AB23: {=IFERROR(INDEX($R$55:$R$176,MATCH(1,($AN$55:$AN$176=U23)*($Q$55:$Q$176="Previsto"), 0) ), "")} -> 1 | AC23: {=IFERROR( INDEX($R$55:$R$176,MATCH(1,($AN$55:$AN$176=U23)*($Q$55:$Q$176="Real"),0)),"")} -> 1 | AD23: =IF(OR(AB23="",AC23=""),"",IF(AC23=100%,"CONCLUÍDO",IF(AC23=0,IF(AB23=0,"PROJETO NÃO INICIADO","FALTA DE ACOMPANHAMENTO"),IF(AC23>AB23,"ADIANTADO",IF(AC23=AB23,"CONFORME PLANEJADO","ATRASO"))))) -> CONCLUÍDO | AE23: 1
O24: 19 | P24: =_xlfn.XLOOKUP(U24,$C$55:$C$176,$A$55:$A$176) -> Redução de custo | Q24: =IFERROR(LARGE($I$55:$I$176,O24)," ") -> 68000 | R24: =_xlfn.XLOOKUP(Q24,$I$55:$I$176,$N$55:$N$176) -> 56610.76 | S24: =_xlfn.XLOOKUP(U24,$C$55:$C$176,$J$55:$J$176) -> 46082 | T24: {=SUMPRODUCT(($C$55:$C$175=U24)*(S$54:$AG$54<=TODAY())*(ISNUMBER(S$56:$AG$176)),S$56:$AG$176)} -> 15439.298 | U24: =IFERROR(HYPERLINK(INDEX($D$55:$D$176,MATCH(Q24,$I$55:$I$176,0)),INDEX($C$55:$C$176,MATCH(Q24,$I$55:$I$176,0)) ), "" ) -> 05 - Empilhadeira - Diadema | Z24: =Q24/$C$5 -> 0.014711971 | AA24: =Z24+AA23 -> 0.73557389 | AB24: {=IFERROR(INDEX($R$55:$R$176,MATCH(1,($AN$55:$AN$176=U24)*($Q$55:$Q$176="Previsto"), 0) ), "")} -> 1 | AC24: {=IFERROR( INDEX($R$55:$R$176,MATCH(1,($AN$55:$AN$176=U24)*($Q$55:$Q$176="Real"),0)),"")} -> 1 | AD24: =IF(OR(AB24="",AC24=""),"",IF(AC24=100%,"CONCLUÍDO",IF(AC24=0,IF(AB24=0,"PROJETO NÃO INICIADO","FALTA DE ACOMPANHAMENTO"),IF(AC24>AB24,"ADIANTADO",IF(AC24=AB24,"CONFORME PLANEJADO","ATRASO"))))) -> CONCLUÍDO | AE24: 1
O25: 20 | P25: =_xlfn.XLOOKUP(U25,$C$55:$C$176,$A$55:$A$176) -> BSW | Q25: =IFERROR(LARGE($I$55:$I$176,O25)," ") -> 63600 | R25: =_xlfn.XLOOKUP(Q25,$I$55:$I$176,$N$55:$N$176) -> 0 | S25: =_xlfn.XLOOKUP(U25,$C$55:$C$176,$J$55:$J$176) -> 46204 | T25: {=SUMPRODUCT(($C$55:$C$175=U25)*(S$54:$AG$54<=TODAY())*(ISNUMBER(S$56:$AG$176)),S$56:$AG$176)} -> 0 | U25: =IFERROR( HYPERLINK( INDEX(Diadema!$D$55:$D$176, MATCH(Q25,Diadema!$I$55:$I$176,0) ), INDEX(Diadema!$C$55:$C$176, MATCH(Q25,Diadema!$I$55:$I$176,0) ) ), "" ) -> 49 - REDUÇÃO DE MP GM000408Z / GM000409Z | Z25: =Q25/$C$5 -> 0.01376002 | AA25: =Z25+AA24 -> 0.74933391 | AB25: {=IFERROR(INDEX($R$55:$R$176,MATCH(1,($AN$55:$AN$176=U25)*($Q$55:$Q$176="Previsto"), 0) ), "")} -> 0.28 | AC25: {=IFERROR( INDEX($R$55:$R$176,MATCH(1,($AN$55:$AN$176=U25)*($Q$55:$Q$176="Real"),0)),"")} -> 1 | AD25: =IF(OR(AB25="",AC25=""),"",IF(AC25=100%,"CONCLUÍDO",IF(AC25=0,IF(AB25=0,"PROJETO NÃO INICIADO","FALTA DE ACOMPANHAMENTO"),IF(AC25>AB25,"ADIANTADO",IF(AC25=AB25,"CONFORME PLANEJADO","ATRASO"))))) -> CONCLUÍDO | AE25: 0.5
O26: Total | Q26: =SUM(Q6:Q25) -> 3463486 | R26: =SUM(R6:R25) -> 1754354.7
A27: 1. KPIs ESTRATÉGICOS
A28: CATEGORIA | B28: KPI | C28: UN | D28: Frequência | E28: TIPO | F28: BASELINE 2025 | G28: META 2026 | H28: Jan | I28: P. Ofensor1 | J28: Fev | K28: P. Ofensor2 | L28: Mar | M28: P. Ofensor3 | N28: Abr | O28: P. Ofensor4 | P28: Mai | Q28: P. Ofensor5 | R28: Jun | S28: P. Ofensor6 | T28: Jul | U28: P. Ofensor7 | V28: Ago | W28: P. Ofensor8 | X28: Set | Y28: P. Ofensor9 | Z28: Out | AA28: P. Ofensor10 | AB28: Nov | AC28: P. Ofensor11 | AD28: Dez | AE28: P. Ofensor12
A29: Financeiro | B29: Margem VA | C29: % | D29: Mensal | E29: Maior Melhor ↑ | F29: 0.346 | G29: 0.361 | H29: 0.321 | I29: Matéria Prima | J29: 0.33 | K29: Matéria Prima | L29: 0.326 | M29: Matéria Prima | N29: 0.358 | O29: Matéria Prima | P29: 0.358 | Q29: Matéria Prima
A30: Financeiro | B30: Custo de Scrap (Refugo) | C30: % | D30: Mensal | E30: Menor Melhor ↓ | F30: 0.003 | G30: 0.002 | H30: 0.00201 | I30: Rachadura | J30: 0.0065 | K30: Rachadura | L30: 0.0042 | M30: Rachadura | N30: 0.0043 | O30: Rachadura | P30: 0.0028 | Q30: Rachadura
A31: Operacional | B31: OEE Prensas Grandes (24) | C31: % | D31: Semanal | E31: Maior Melhor ↑ | F31: 0.501 | G31: 0.56 | H31: 0.4843 | I31: Falta de energia | J31: =J33*J34*J35 -> 0.51104832 | K31: Manutenção | L31: =L33*L34*L35 -> 0.66519873 | M31: Manutenção | N31: 0.7202 | O31: Manutenção | P31: 0.6949 | Q31: Manutenção
A32: Operacional | B32: Eficiência de MO Planta | C32: % | D32: Mensal | E32: Maior Melhor ↑ | F32: 0.562 | G32: 0.64 | H32: 0.551 | I32: Falta de energia | J32: 0.561 | K32: Falta de energia | L32: 0.53 | M32: Falta de OP | N32: 0.508 | O32: Falta de OP | P32: 0.523 | Q32: Falta de OP
A33: Operacional | B33: Performance Prensas Grandes (24) | C33: % | D33: Semanal | E33: Maior Melhor ↑ | F33: 0.9261 | G33: 0.95 | H33: 0.8992 | I33: Falta de energia | J33: 0.8879 | K33: Manutenção | L33: 0.9508 | M33: Manutenção | N33: 0.9717 | O33: Manutenção | P33: 0.9461 | Q33: Manutenção
A34: Operacional | B34: Qualidade Prensas Grandes (24) | C34: % | D34: Semanal | E34: Maior Melhor ↑ | F34: 0.955 | G34: 0.965 | H34: 0.9995 | I34: Ferramentaria | J34: 0.9996 | K34: Ferramentaria | L34: 0.9996 | M34: Manutenção | N34: 0.9997 | O34: Manutenção | P34: 0.9997 | Q34: Manutenção
A35: Operacional | B35: Disponibilidade Prensas Grandes (24) | C35: % | D35: Semanal | E35: Maior Melhor ↑ | F35: 0.959 | G35: 0.97 | H35: 0.5389 | I35: Ferramentaria | J35: 0.5758 | K35: Ferramentaria | L35: 0.6999 | M35: Manutenção | N35: 0.7414 | O35: Manutenção | P35: 0.7347 | Q35: Manutenção
A36: Operacional | B36: MTBF (Manutenção) | C36: h | D36: Mensal | E36: Maior Melhor ↑ | F36: 13:00 | G36: 15:00 | H36: 0.625 | I36: Quebra mecânica | J36: 0.54166667 | K36: Quebra mecânica | L36: 0.875 | M36: Quebra mecânica | N36: 1.5 | O36: Quebra mecânica | P36: 1.5 | Q36: Quebra mecânica
A37: Operacional | B37: MTTR (Manutenção) | C37: h | D37: Mensal | E37: Menor Melhor ↓ | F37: 0:33 | G37: 0:30 | H37: 00:15 | I37: Problema com CLP | J37: 0.048611111 | K37: Quebra mecânica | L37: 0.052083333 | M37: Quebra mecânica | N37: 0.031944444 | O37: Quebra mecânica | P37: 0.038888889 | Q37: Quebra mecânica
A38: Operacional | B38: Horas Extras | C38: Valor | D38: Mensal | E38: Menor Melhor ↓ | F38: 91000 | G38: 73000 | H38: 108458.31 | I38: Manutenção | J38: 81579 | K38: Manutenção | L38: =5000+87000 -> 92000 | M38: Manutenção | N38: 97860 | O38: Manutenção | P38: 96507 | Q38: Manutenção
A39: Operacional | B39: Acuracidade Estoque | C39: Valor | D39: Semanal | E39: Menor Melhor ↓ | F39: 458000 | G39: 358737 | H39: 29000 | I39: Apontamento incorreto | J39: 30000 | K39: Apontamento incorreto | L39: 6176 | M39: Apontamento incorreto | N39: 5680 | O39: Mat. sem saldo | P39: 213.12 | Q39: Mat. sem saldo
A40: Qualidade | B40: PPM Interno | C40: ppm | D40: Mensal | E40: Menor Melhor ↓ | F40: - | G40: 900 | H40: 60593 | I40: Rebarba | J40: 57795 | K40: Rebarba | L40: 19052 | M40: Rebarba | N40: 59710 | O40: Rebarba | P40: 60162 | Q40: Rebarba
A41: Qualidade | B41: PPM Externo | C41: ppm | D41: Mensal | E41: Menor Melhor ↓ | F41: 3347 | G41: 3000 | H41: 1 | I41: Solda irregular | J41: 476 | K41: Falta de rosca | L41: 80 | M41: Quebra de FIFO | N41: 30 | O41: Falta de componente | P41: 1 | Q41: Dimensional
...

Sheet Jarinu
A1: DASHBOARD EXECUTIVO - UNIDADE JARINU
A2: Gestão Estratégica de Projetos e Redução de Custos | Grupo Delga | 2026
A4: META DA UNIDADE | B4: RETORNO PREVISTO (Total) | C4: PREVISTO 2026 | E4: 💰 RETORNO VALIDADO | G4: 💰 RETORNO REAL | J4: % ATINGIMENTO DA META | L4: INICIATIVAS | O4: TOP 20 Raking de Projetos Valorizados
A5: =Parâmetros!E8 -> 5356000 | B5: =SUM(I55:I128) -> 3919443 | C5: =SUMIF(Q55:Q128,"Previsto",AI55:AI128) -> 2392012.2 | E5: =SUM(N55:N128) -> 2819031.8 | G5: =SUMIF(Q55:Q128,"Real",AI55:AI128) -> 393297.17 | J5: =G5/A5 -> 0.073431137 | L5: =SUM(I9:I11) -> 34 | O5: POS | P5: Tipo | Q5: Valor Previsto | R5: Valor Previsto Custos | S5: Retorno Previsto | T5: Retorno Real até hoje | U5: Projetos | Z5: Peso | AA5: Pareto | AB5: % Previsto | AC5: % Real | AD5: Planejado | AE5: % Responsabilidade Delga
O6: {=_xlfn.SEQUENCE(20)} -> 1 | P6: =_xlfn.XLOOKUP(U6,$C$55:$C$128,$A$55:$A$128) -> BSW | Q6: =MAX(I55:I128) -> 1063359 | R6: =_xlfn.XLOOKUP(Q6,$I$55:$I$128,$N$55:$N$128) -> 1145830.2 | S6: =_xlfn.XLOOKUP(U6,$B$55:$B$144,$I$55:$I$144) -> #N/A | T6: {=SUMPRODUCT(($B$55:$B$143=U6)*(S$54:$AG$54<=TODAY())*(ISNUMBER(R$56:$AF$144)),R$56:$AF$144)} -> #REF! | U6: =IFERROR(HYPERLINK(INDEX($D$55:$D$128,MATCH(Q6,$I$55:$I$128,0)),INDEX($C$55:$C$128,MATCH(Q6,$I$55:$I$128,0)) ), "" ) -> 06 - Redução consumo MTP aplicando tolerância mínima | Z6: =Q6/$C$5 -> 0.44454581 | AA6: =Pareto!E70 -> 0.2713036 | AB6: {=IFERROR(INDEX($R$55:$R$128,MATCH(1,($AN$55:$AN$128=U6)*($Q$55:$Q$128="Previsto"), 0) ), "")} -> 0.32939189 | AC6: 0.29 | AD6: =IF(OR(AB6="",AC6=""),"",IF(AC6=100%,"CONCLUÍDO",IF(AC6=0,IF(AB6=0,"PROJETO NÃO INICIADO","FALTA DE ACOMPANHAMENTO"),IF(AC6>AB6,"ADIANTADO",IF(AC6=AB6,"CONFORME PLANEJADO","ATRASO"))))) -> ATRASO | AE6: {=_xlfn.XLOOKUP($U$6:$U$24,$C$55:$C$128,$P$55:$P$128)} -> 0.1
A7: 📊 SAVING PREVISTO POR PILAR | H7: 📋 STATUS DAS INICIATIVAS | K7: 🏭 INDICADORES OPERACIONAIS | O7: 2 | P7: =_xlfn.XLOOKUP(U7,$C$55:$C$128,$A$55:$A$128) -> BSW | Q7: =IFERROR(LARGE($I$55:$I$128,O7)," ") -> 513721 | R7: =_xlfn.XLOOKUP(Q7,$I$55:$I$128,$N$55:$N$128) -> 0 | S7: =_xlfn.XLOOKUP(U7,$B$55:$B$144,$I$55:$I$144) -> #N/A | T7: {=SUMPRODUCT(($B$55:$B$143=U7)*(S$54:$AG$54<=TODAY())*(ISNUMBER(R$56:$AF$144)),R$56:$AF$144)} -> #REF! | U7: =IFERROR(HYPERLINK(INDEX($D$55:$D$128,MATCH(Q7,$I$55:$I$128,0)),INDEX($C$55:$C$128,MATCH(Q7,$I$55:$I$128,0)) ), "" ) -> 03 - Redução de consumo de MP dos blanks com a técnica de corte Wave | Z7: =Q7/$C$5 -> 0.21476521 | AA7: =Pareto!E71 -> 0.4023735 | AB7: {=IFERROR(INDEX($R$55:$R$128,MATCH(1,($AN$55:$AN$128=U7)*($Q$55:$Q$128="Previsto"), 0) ), "")} | AC7: {=IFERROR( INDEX($R$55:$R$128,MATCH(1,($AN$55:$AN$128=U7)*($Q$55:$Q$128="Real"),0)),"")} | AD7: =IF(OR(AB7="",AC7=""),"",IF(AC7=100%,"CONCLUÍDO",IF(AC7=0,IF(AB7=0,"PROJETO NÃO INICIADO","FALTA DE ACOMPANHAMENTO"),IF(AC7>AB7,"ADIANTADO",IF(AC7=AB7,"CONFORME PLANEJADO","ATRASO"))))) | AE7: 0.9
A8: Pilar | B8: Qtd. | C8: Saving (R$) | D8: Saving Validado 2026 | E8: % Total | F8: Barra | H8: Status | I8: Qtd. | J8: R$ Previsto | K8: Aderência SPD: Unidade | L8: Aderência SPD: Auditado | M8: Análise de Margem (Form 206) | O8: 3 | P8: =_xlfn.XLOOKUP(U8,$C$55:$C$128,$A$55:$A$128) -> BSW | Q8: =IFERROR(LARGE($I$55:$I$128,O8)," ") -> 435138 | R8: =_xlfn.XLOOKUP(Q8,$I$55:$I$128,$N$55:$N$128) -> 442663.07 | S8: =_xlfn.XLOOKUP(U8,$B$55:$B$144,$I$55:$I$144) -> #N/A | T8: {=SUMPRODUCT(($B$55:$B$143=U8)*(S$54:$AG$54<=TODAY())*(ISNUMBER(R$56:$AF$144)),R$56:$AF$144)} -> #REF! | U8: =IFERROR(HYPERLINK(INDEX($D$55:$D$128,MATCH(Q8,$I$55:$I$128,0)),INDEX($C$55:$C$128,MATCH(Q8,$I$55:$I$128,0)) ), "" ) -> 27 - Redução consumo MTP aplicando tolerância mínima curva B | Z8: =Q8/$C$5 -> 0.18191295 | AA8: =Pareto!E72 -> 0.51339387 | AB8: {=IFERROR(INDEX($R$55:$R$128,MATCH(1,($AN$55:$AN$128=U8)*($Q$55:$Q$128="Previsto"), 0) ), "")} -> 0.2 | AC8: {=IFERROR( INDEX($R$55:$R$128,MATCH(1,($AN$55:$AN$128=U8)*($Q$55:$Q$128="Real"),0)),"")} -> 0 | AD8: =IF(OR(AB8="",AC8=""),"",IF(AC8=100%,"CONCLUÍDO",IF(AC8=0,IF(AB8=0,"PROJETO NÃO INICIADO","FALTA DE ACOMPANHAMENTO"),IF(AC8>AB8,"ADIANTADO",IF(AC8=AB8,"CONFORME PLANEJADO","ATRASO"))))) -> FALTA DE ACOMPANHAMENTO | AE8: 0
A9: Kaizen | B9: =COUNTIF($A$55:$A$128,A9) -> 4 | C9: =SUMIF($A$55:$A$128,A9,$I$55:$I$128) -> 731000 | D9: =SUMIF($A$55:$A$128,A9,$N$55:$N$128) -> 390000 | E9: =IF($D$13=0,"",D9/$D$13) -> 0.13834537 | F9: =E9 -> 0.13834537 | H9: ✓ Concluído | I9: =COUNTIF($O$55:$O$128,H9) -> 7 | J9: =SUMIF($O$55:$O$128,H9,$I$55:$I$128) -> 414120 | O9: 4 | P9: =_xlfn.XLOOKUP(U9,$C$55:$C$128,$A$55:$A$128) -> Kaizen | Q9: =IFERROR(LARGE($I$55:$I$128,O9)," ") -> 390000 | R9: =_xlfn.XLOOKUP(Q9,$I$55:$I$128,$N$55:$N$128) -> 390000 | S9: =_xlfn.XLOOKUP(U9,$B$55:$B$144,$I$55:$I$144) -> #N/A | T9: {=SUMPRODUCT(($B$55:$B$143=U9)*(S$54:$AG$54<=TODAY())*(ISNUMBER(R$56:$AF$144)),R$56:$AF$144)} -> #REF! | U9: =IFERROR(HYPERLINK(INDEX($D$55:$D$128,MATCH(Q9,$I$55:$I$128,0)),INDEX($C$55:$C$128,MATCH(Q9,$I$55:$I$128,0)) ), "" ) -> 36 - Venda Robos | Z9: =Q9/$C$5 -> 0.16304265 | AA9: =Pareto!E73 -> 0.6128978 | AB9: {=IFERROR(INDEX($R$55:$R$128,MATCH(1,($AN$55:$AN$128=U9)*($Q$55:$Q$128="Previsto"), 0) ), "")} -> 1 | AC9: {=IFERROR( INDEX($R$55:$R$128,MATCH(1,($AN$55:$AN$128=U9)*($Q$55:$Q$128="Real"),0)),"")} -> 1 | AD9: =IF(OR(AB9="",AC9=""),"",IF(AC9=100%,"CONCLUÍDO",IF(AC9=0,IF(AB9=0,"PROJETO NÃO INICIADO","FALTA DE ACOMPANHAMENTO"),IF(AC9>AB9,"ADIANTADO",IF(AC9=AB9,"CONFORME PLANEJADO","ATRASO"))))) -> CONCLUÍDO | AE9: 0
A10: Redução de Custo | B10: =COUNTIF($A$55:$A$128,A10) -> 19 | C10: =SUMIF($A$55:$A$128,A10,$I$55:$I$128) -> 466969 | D10: =SUMIF($A$55:$A$128,A10,$N$55:$N$128) -> 549981.18 | E10: =IF($D$13=0,"",D10/$D$13) -> 0.19509577 | F10: =E10 -> 0.19509577 | H10: ⏳ Em Execução | I10: =COUNTIF($O$55:$O$128,H10) -> 23 | J10: =SUMIF($O$55:$O$128,H10,$I$55:$I$128) -> 3403113 | K10: =E159 -> 0.71428571 | L10: =F159 -> 0.42857143 | M10: =L154 -> 0.43333333 | O10: 5 | P10: =_xlfn.XLOOKUP(U10,$C$55:$C$128,$A$55:$A$128) -> BSW | Q10: =IFERROR(LARGE($I$55:$I$128,O10)," ") -> 308498 | R10: =_xlfn.XLOOKUP(Q10,$I$55:$I$128,$N$55:$N$128) -> 209476.06 | S10: =_xlfn.XLOOKUP(U10,$B$55:$B$144,$I$55:$I$144) -> #N/A | T10: {=SUMPRODUCT(($B$55:$B$143=U10)*(S$54:$AG$54<=TODAY())*(ISNUMBER(R$56:$AF$144)),R$56:$AF$144)} -> #REF! | U10: =IFERROR(HYPERLINK(INDEX($D$55:$D$128,MATCH(Q10,$I$55:$I$128,0)),INDEX($C$55:$C$128,MATCH(Q10,$I$55:$I$128,0)) ), "" ) -> 28 - Redução consumo MTP aplicando tolerância mínima curva C | Z10: =Q10/$C$5 -> 0.12897008 | AA10: =Pareto!E74 -> 0.69160746 | AB10: {=IFERROR(INDEX($R$55:$R$128,MATCH(1,($AN$55:$AN$128=U10)*($Q$55:$Q$128="Previsto"), 0) ), "")} -> 0.2 | AC10: {=IFERROR( INDEX($R$55:$R$128,MATCH(1,($AN$55:$AN$128=U10)*($Q$55:$Q$128="Real"),0)),"")} -> 0.21052632 | AD10: =IF(OR(AB10="",AC10=""),"",IF(AC10=100%,"CONCLUÍDO",IF(AC10=0,IF(AB10=0,"PROJETO NÃO INICIADO","FALTA DE ACOMPANHAMENTO"),IF(AC10>AB10,"ADIANTADO",IF(AC10=AB10,"CONFORME PLANEJADO","ATRASO"))))) -> ADIANTADO | AE10: 0
A11: Você Resolve | B11: =COUNTIF($A$55:$A$128,A11) -> 1 | C11: =SUMIF($A$55:$A$128,A11,$I$55:$I$128) -> 0 | D11: =SUMIF($A$55:$A$128,A11,$N$55:$N$128) -> 0 | E11: =IF($D$13=0,"",D11/$D$13) -> 0 | F11: =E11 -> 0 | H11: 📝 Não iniciado | I11: =COUNTIF($O$55:$O$128,H11) -> 4 | J11: =SUMIF($O$55:$O$128,H11,$I$55:$I$128) -> 0 | O11: 6 | P11: =_xlfn.XLOOKUP(U11,$C$55:$C$128,$A$55:$A$128) -> Redução de custo | Q11: =IFERROR(LARGE($I$55:$I$128,O11)," ") -> 306000 | R11: =_xlfn.XLOOKUP(Q11,$I$55:$I$128,$N$55:$N$128) -> 306000 | S11: =_xlfn.XLOOKUP(U11,$B$55:$B$144,$I$55:$I$144) -> #N/A | T11: {=SUMPRODUCT(($B$55:$B$143=U11)*(S$54:$AG$54<=TODAY())*(ISNUMBER(R$56:$AF$144)),R$56:$AF$144)} -> #REF! | U11: =IFERROR(HYPERLINK(INDEX($D$55:$D$128,MATCH(Q11,$I$55:$I$128,0)),INDEX($C$55:$C$128,MATCH(Q11,$I$55:$I$128,0)) ), "" ) -> 30 - Redução de Refugo | Z11: =Q11/$C$5 -> 0.12792577 | AA11: =Pareto!E75 -> 0.76967977 | AB11: {=IFERROR(INDEX($R$55:$R$128,MATCH(1,($AN$55:$AN$128=U11)*($Q$55:$Q$128="Previsto"), 0) ), "")} -> 0.8 | AC11: {=IFERROR( INDEX($R$55:$R$128,MATCH(1,($AN$55:$AN$128=U11)*($Q$55:$Q$128="Real"),0)),"")} -> 0.8 | AD11: =IF(OR(AB11="",AC11=""),"",IF(AC11=100%,"CONCLUÍDO",IF(AC11=0,IF(AB11=0,"PROJETO NÃO INICIADO","FALTA DE ACOMPANHAMENTO"),IF(AC11>AB11,"ADIANTADO",IF(AC11=AB11,"CONFORME PLANEJADO","ATRASO"))))) -> CONFORME PLANEJADO | AE11: 0
A12: BSW | B12: =COUNTIF($A$55:$A$128,A12) -> 13 | C12: =SUMIF($A$55:$A$128,A12,$I$55:$I$128) -> 2721474 | D12: =SUMIF($A$55:$A$128,A12,$N$55:$N$128) -> 1879050.6 | E12: =IF($D$13=0,"",D12/$D$13) -> 0.66655886 | F12: =E12 -> 0.66655886 | O12: 7 | P12: =_xlfn.XLOOKUP(U12,$C$55:$C$128,$A$55:$A$128) -> Kaizen | Q12: =IFERROR(LARGE($I$55:$I$128,O12)," ") -> 301000 | R12: =_xlfn.XLOOKUP(Q12,$I$55:$I$128,$N$55:$N$128) -> 0 | S12: =_xlfn.XLOOKUP(U12,$B$55:$B$144,$I$55:$I$144) -> #N/A | T12: {=SUMPRODUCT(($B$55:$B$143=U12)*(S$54:$AG$54<=TODAY())*(ISNUMBER(R$56:$AF$144)),R$56:$AF$144)} -> #REF! | U12: =IFERROR(HYPERLINK(INDEX($D$55:$D$128,MATCH(Q12,$I$55:$I$128,0)),INDEX($C$55:$C$128,MATCH(Q12,$I$55:$I$128,0)) ), "" ) -> 32 - Empilhadeiras Elétricas | Z12: =Q12/$C$5 -> 0.12583548 | AA12: =Pareto!E76 -> 0.8464764 | AB12: {=IFERROR(INDEX($R$55:$R$128,MATCH(1,($AN$55:$AN$128=U12)*($Q$55:$Q$128="Previsto"), 0) ), "")} -> 0.92307692 | AC12: {=IFERROR( INDEX($R$55:$R$128,MATCH(1,($AN$55:$AN$128=U12)*($Q$55:$Q$128="Real"),0)),"")} -> 0 | AD12: =IF(OR(AB12="",AC12=""),"",IF(AC12=100%,"CONCLUÍDO",IF(AC12=0,IF(AB12=0,"PROJETO NÃO INICIADO","FALTA DE ACOMPANHAMENTO"),IF(AC12>AB12,"ADIANTADO",IF(AC12=AB12,"CONFORME PLANEJADO","ATRASO"))))) -> FALTA DE ACOMPANHAMENTO | AE12: 0
A13: TOTAL | B13: =SUM(B9:B12) -> 37 | C13: =SUM(C9:C12) -> 3919443 | D13: =SUM(D9:D12) -> 2819031.8 | E13: =SUM(E9:E12) -> 1 | O13: 8 | P13: =_xlfn.XLOOKUP(U13,$C$55:$C$128,$A$55:$A$128) -> BSW | Q13: =IFERROR(LARGE($I$55:$I$128,O13)," ") -> 102967 | R13: =_xlfn.XLOOKUP(Q13,$I$55:$I$128,$N$55:$N$128) -> 0 | S13: =_xlfn.XLOOKUP(U13,$B$55:$B$144,$I$55:$I$144) -> #N/A | T13: {=SUMPRODUCT(($B$55:$B$143=U13)*(S$54:$AG$54<=TODAY())*(ISNUMBER(R$56:$AF$144)),R$56:$AF$144)} -> #REF! | U13: =IFERROR(HYPERLINK(INDEX($D$55:$D$128,MATCH(Q13,$I$55:$I$128,0)),INDEX($C$55:$C$128,MATCH(Q13,$I$55:$I$128,0)) ), "" ) -> 19 - Redução da largura da bobina mãe do Curvão | Z13: =Q13/$C$5 -> 0.043046185 | AA13: =Pareto!E77 -> 0.87274722 | AB13: {=IFERROR(INDEX($R$55:$R$128,MATCH(1,($AN$55:$AN$128=U13)*($Q$55:$Q$128="Previsto"), 0) ), "")} -> 0 | AC13: {=IFERROR( INDEX($R$55:$R$128,MATCH(1,($AN$55:$AN$128=U13)*($Q$55:$Q$128="Real"),0)),"")} -> 0 | AD13: =IF(OR(AB13="",AC13=""),"",IF(AC13=100%,"CONCLUÍDO",IF(AC13=0,IF(AB13=0,"PROJETO NÃO INICIADO","FALTA DE ACOMPANHAMENTO"),IF(AC13>AB13,"ADIANTADO",IF(AC13=AB13,"CONFORME PLANEJADO","ATRASO"))))) -> PROJETO NÃO INICIADO | AE13: 0.5
H14: ; | O14: 9 | P14: =_xlfn.XLOOKUP(U14,$C$55:$C$128,$A$55:$A$128) -> BSW | Q14: =IFERROR(LARGE($I$55:$I$128,O14)," ") -> 91444 | R14: =_xlfn.XLOOKUP(Q14,$I$55:$I$128,$N$55:$N$128) -> 0 | S14: =_xlfn.XLOOKUP(U14,$B$55:$B$144,$I$55:$I$144) -> #N/A | T14: {=SUMPRODUCT(($B$55:$B$143=U14)*(S$54:$AG$54<=TODAY())*(ISNUMBER(R$56:$AF$144)),R$56:$AF$144)} -> #REF! | U14: =IFERROR(HYPERLINK(INDEX($D$55:$D$128,MATCH(Q14,$I$55:$I$128,0)),INDEX($C$55:$C$128,MATCH(Q14,$I$55:$I$128,0)) ), "" ) -> 05 - Aplicar borda aparadas nas bobinas | Z14: =Q14/$C$5 -> 0.038228902 | AA14: =Pareto!E78 -> 0.89607809 | AB14: {=IFERROR(INDEX($R$55:$R$128,MATCH(1,($AN$55:$AN$128=U14)*($Q$55:$Q$128="Previsto"), 0) ), "")} -> 0.41666667 | AC14: {=IFERROR( INDEX($R$55:$R$128,MATCH(1,($AN$55:$AN$128=U14)*($Q$55:$Q$128="Real"),0)),"")} -> 0.33333333 | AD14: =IF(OR(AB14="",AC14=""),"",IF(AC14=100%,"CONCLUÍDO",IF(AC14=0,IF(AB14=0,"PROJETO NÃO INICIADO","FALTA DE ACOMPANHAMENTO"),IF(AC14>AB14,"ADIANTADO",IF(AC14=AB14,"CONFORME PLANEJADO","ATRASO"))))) -> ATRASO | AE14: 0.8
F15: VA | G15: =SUMIF($B$55:$B$176,F15,$N$55:$N$176) -> 1879050.6 | O15: 10 | P15: =_xlfn.XLOOKUP(U15,$C$55:$C$128,$A$55:$A$128) -> Redução de custo | Q15: =IFERROR(LARGE($I$55:$I$128,O15)," ") -> 90850 | R15: =_xlfn.XLOOKUP(Q15,$I$55:$I$128,$N$55:$N$128) -> 165883.52 | S15: =_xlfn.XLOOKUP(U15,$B$55:$B$144,$I$55:$I$144) -> #N/A | T15: {=SUMPRODUCT(($B$55:$B$143=U15)*(S$54:$AG$54<=TODAY())*(ISNUMBER(R$56:$AF$144)),R$56:$AF$144)} -> #REF! | U15: =IFERROR(HYPERLINK(INDEX($D$55:$D$128,MATCH(Q15,$I$55:$I$128,0)),INDEX($C$55:$C$128,MATCH(Q15,$I$55:$I$128,0)) ), "" ) -> 24 - Redução de consumo de MTP China 1 porca (-10 mm) | Z15: =Q15/$C$5 -> 0.037980576 | AA15: =Pareto!E79 -> 0.9192574 | AB15: {=IFERROR(INDEX($R$55:$R$128,MATCH(1,($AN$55:$AN$128=U15)*($Q$55:$Q$128="Previsto"), 0) ), "")} -> 0.875 | AC15: {=IFERROR( INDEX($R$55:$R$128,MATCH(1,($AN$55:$AN$128=U15)*($Q$55:$Q$128="Real"),0)),"")} -> 0 | AD15: =IF(OR(AB15="",AC15=""),"",IF(AC15=100%,"CONCLUÍDO",IF(AC15=0,IF(AB15=0,"PROJETO NÃO INICIADO","FALTA DE ACOMPANHAMENTO"),IF(AC15>AB15,"ADIANTADO",IF(AC15=AB15,"CONFORME PLANEJADO","ATRASO"))))) -> FALTA DE ACOMPANHAMENTO | AE15: 0
